The following values were not passed to `accelerate launch` and had defaults used instead:
		More than one GPU was found, enabling multi-GPU training.
		If this was unintended please pass in `--num_processes=1`.
	`--mixed_precision` was set to a value of `'no'`
	`--dynamo_backend` was set to a value of `'no'`
To avoid this warning pass in values for each of the problematic parameters or run `accelerate config`.
  File "/home/s0214/.conda/envs/monster/bin/python", line 1
SyntaxError: Non-UTF-8 code starting with '\x80' in file /home/s0214/.conda/envs/monster/bin/python on line 2, but no encoding declared; see http://python.org/dev/peps/pep-0263/ for details
  File "/home/s0214/.conda/envs/monster/bin/python", line 1
SyntaxError: Non-UTF-8 code starting with '\x80' in file /home/s0214/.conda/envs/monster/bin/python on line 2, but no encoding declared; see http://python.org/dev/peps/pep-0263/ for details
  File "/home/s0214/.conda/envs/monster/bin/python", line 1
SyntaxError: Non-UTF-8 code starting with '\x80' in file /home/s0214/.conda/envs/monster/bin/python on line 2, but no encoding declared; see http://python.org/dev/peps/pep-0263/ for details
  File "/home/s0214/.conda/envs/monster/bin/python", line 1
SyntaxError: Non-UTF-8 code starting with '\x80' in file /home/s0214/.conda/envs/monster/bin/python on line 2, but no encoding declared; see http://python.org/dev/peps/pep-0263/ for details
[2025-08-10 20:18:57,030] torch.distributed.elastic.multiprocessing.api: [ERROR] failed (exitcode: 1) local_rank: 0 (pid: 3977155) of binary: /home/s0214/.conda/envs/monster/bin/python
Traceback (most recent call last):
  File "/home/s0214/.conda/envs/monster/bin/accelerate", line 8, in <module>
    sys.exit(main())
  File "/home/s0214/.conda/envs/monster/lib/python3.8/site-packages/accelerate/commands/accelerate_cli.py", line 48, in main
    args.func(args)
  File "/home/s0214/.conda/envs/monster/lib/python3.8/site-packages/accelerate/commands/launch.py", line 1159, in launch_command
    multi_gpu_launcher(args)
  File "/home/s0214/.conda/envs/monster/lib/python3.8/site-packages/accelerate/commands/launch.py", line 793, in multi_gpu_launcher
    distrib_run.run(args)
  File "/home/s0214/.conda/envs/monster/lib/python3.8/site-packages/torch/distributed/run.py", line 797, in run
    elastic_launch(
  File "/home/s0214/.conda/envs/monster/lib/python3.8/site-packages/torch/distributed/launcher/api.py", line 134, in __call__
    return launch_agent(self._config, self._entrypoint, list(args))
  File "/home/s0214/.conda/envs/monster/lib/python3.8/site-packages/torch/distributed/launcher/api.py", line 264, in launch_agent
    raise ChildFailedError(
torch.distributed.elastic.multiprocessing.errors.ChildFailedError: 
============================================================
/home/s0214/.conda/envs/monster/bin/python FAILED
------------------------------------------------------------
Failures:
[1]:
  time      : 2025-08-10_20:18:57
  host      : tesla28
  rank      : 1 (local_rank: 1)
  exitcode  : 1 (pid: 3977156)
  error_file: <N/A>
  traceback : To enable traceback see: https://pytorch.org/docs/stable/elastic/errors.html
[2]:
  time      : 2025-08-10_20:18:57
  host      : tesla28
  rank      : 2 (local_rank: 2)
  exitcode  : 1 (pid: 3977157)
  error_file: <N/A>
  traceback : To enable traceback see: https://pytorch.org/docs/stable/elastic/errors.html
[3]:
  time      : 2025-08-10_20:18:57
  host      : tesla28
  rank      : 3 (local_rank: 3)
  exitcode  : 1 (pid: 3977158)
  error_file: <N/A>
  traceback : To enable traceback see: https://pytorch.org/docs/stable/elastic/errors.html
------------------------------------------------------------
Root Cause (first observed failure):
[0]:
  time      : 2025-08-10_20:18:57
  host      : tesla28
  rank      : 0 (local_rank: 0)
  exitcode  : 1 (pid: 3977155)
  error_file: <N/A>
  traceback : To enable traceback see: https://pytorch.org/docs/stable/elastic/errors.html
============================================================
