Both `sys_prefix` and `user` level settings are read-only, cannot auto-migrate `disabledExtensions` to `lockedExtensions`
[I 2025-09-25 04:22:37.665 ServerApp] jupyter_lsp | extension was successfully linked.
[I 2025-09-25 04:22:37.670 ServerApp] jupyter_server_terminals | extension was successfully linked.
[I 2025-09-25 04:22:37.676 ServerApp] jupyterlab | extension was successfully linked.
[I 2025-09-25 04:22:37.681 ServerApp] notebook | extension was successfully linked.
[I 2025-09-25 04:22:38.101 ServerApp] notebook_shim | extension was successfully linked.
[I 2025-09-25 04:22:38.175 ServerApp] notebook_shim | extension was successfully loaded.
[I 2025-09-25 04:22:38.177 ServerApp] jupyter_lsp | extension was successfully loaded.
[I 2025-09-25 04:22:38.181 ServerApp] jupyter_server_terminals | extension was successfully loaded.
[I 2025-09-25 04:22:38.193 LabApp] JupyterLab extension loaded from /home/s0214/.conda/envs/monster/lib/python3.8/site-packages/jupyterlab
[I 2025-09-25 04:22:38.193 LabApp] JupyterLab application directory is /misc/home4/s0214/.conda/envs/monster/share/jupyter/lab
[I 2025-09-25 04:22:38.197 LabApp] Extension Manager is 'pypi'.
[I 2025-09-25 04:22:38.301 ServerApp] jupyterlab | extension was successfully loaded.
[I 2025-09-25 04:22:38.309 ServerApp] notebook | extension was successfully loaded.
[I 2025-09-25 04:22:38.310 ServerApp] Serving notebooks from local directory: /misc/home6/s0214/MonSter
[I 2025-09-25 04:22:38.310 ServerApp] Jupyter Server 2.14.2 is running at:
[I 2025-09-25 04:22:38.310 ServerApp] http://tesla-v100:8888/tree?token=b628fef4854373fa3ad9a3d3d8c5ea5b2bfbb6aa4c79b4e6
[I 2025-09-25 04:22:38.310 ServerApp]     http://127.0.0.1:8888/tree?token=b628fef4854373fa3ad9a3d3d8c5ea5b2bfbb6aa4c79b4e6
[I 2025-09-25 04:22:38.310 ServerApp] Use Control-C to stop this server and shut down all kernels (twice to skip confirmation).
[C 2025-09-25 04:22:38.355 ServerApp] 
    
    To access the server, open this file in a browser:
        file:///misc/home4/s0214/.local/share/jupyter/runtime/jpserver-1911909-open.html
    Or copy and paste one of these URLs:
        http://tesla-v100:8888/tree?token=b628fef4854373fa3ad9a3d3d8c5ea5b2bfbb6aa4c79b4e6
        http://127.0.0.1:8888/tree?token=b628fef4854373fa3ad9a3d3d8c5ea5b2bfbb6aa4c79b4e6
[I 2025-09-25 04:22:38.530 ServerApp] Skipped non-installed server(s): basedpyright, bash-language-server, dockerfile-language-server-nodejs, javascript-typescript-langserver, jedi-language-server, julia-language-server, pyrefly, pyright, python-language-server, python-lsp-server, r-languageserver, sql-language-server, texlab, typescript-language-server, unified-language-server, vscode-css-languageserver-bin, vscode-html-languageserver-bin, vscode-json-languageserver-bin, yaml-language-server
[W 2025-09-25 04:22:44.468 ServerApp] wrote error: 'Forbidden'
    Traceback (most recent call last):
      File "/home/s0214/.conda/envs/monster/lib/python3.8/site-packages/tornado/web.py", line 1788, in _execute
        result = method(*self.path_args, **self.path_kwargs)
      File "/home/s0214/.conda/envs/monster/lib/python3.8/site-packages/tornado/web.py", line 3289, in wrapper
        url = self.get_login_url()
      File "/home/s0214/.conda/envs/monster/lib/python3.8/site-packages/jupyter_server/base/handlers.py", line 783, in get_login_url
        raise web.HTTPError(403)
    tornado.web.HTTPError: HTTP 403: Forbidden
[W 2025-09-25 04:22:44.472 ServerApp] 403 GET /api/kernelspecs?1758756164464 (@172.16.33.3) 4.64ms referer=None
[W 2025-09-25 04:22:53.166 ServerApp] wrote error: 'Forbidden'
    Traceback (most recent call last):
      File "/home/s0214/.conda/envs/monster/lib/python3.8/site-packages/tornado/web.py", line 1788, in _execute
        result = method(*self.path_args, **self.path_kwargs)
      File "/home/s0214/.conda/envs/monster/lib/python3.8/site-packages/tornado/web.py", line 3289, in wrapper
        url = self.get_login_url()
      File "/home/s0214/.conda/envs/monster/lib/python3.8/site-packages/jupyter_server/base/handlers.py", line 783, in get_login_url
        raise web.HTTPError(403)
    tornado.web.HTTPError: HTTP 403: Forbidden
[W 2025-09-25 04:22:53.167 ServerApp] 403 GET /api/sessions?1758756173162 (@172.16.33.3) 1.48ms referer=None
[W 2025-09-25 04:22:57.161 ServerApp] wrote error: 'Forbidden'
    Traceback (most recent call last):
      File "/home/s0214/.conda/envs/monster/lib/python3.8/site-packages/tornado/web.py", line 1788, in _execute
        result = method(*self.path_args, **self.path_kwargs)
      File "/home/s0214/.conda/envs/monster/lib/python3.8/site-packages/tornado/web.py", line 3289, in wrapper
        url = self.get_login_url()
      File "/home/s0214/.conda/envs/monster/lib/python3.8/site-packages/jupyter_server/base/handlers.py", line 783, in get_login_url
        raise web.HTTPError(403)
    tornado.web.HTTPError: HTTP 403: Forbidden
[W 2025-09-25 04:22:57.162 ServerApp] 403 GET /api/kernels/6e075d6c-26b2-4b58-be89-fe33daa58a24?1758756177156 (@172.16.33.3) 0.96ms referer=None
[I 2025-09-25 04:22:59.224 ServerApp] 302 GET / (@172.16.33.3) 0.34ms
[W 2025-09-25 04:22:59.229 ServerApp] wrote error: 'Forbidden'
    Traceback (most recent call last):
      File "/home/s0214/.conda/envs/monster/lib/python3.8/site-packages/tornado/web.py", line 1788, in _execute
        result = method(*self.path_args, **self.path_kwargs)
      File "/home/s0214/.conda/envs/monster/lib/python3.8/site-packages/tornado/web.py", line 3289, in wrapper
        url = self.get_login_url()
      File "/home/s0214/.conda/envs/monster/lib/python3.8/site-packages/jupyter_server/base/handlers.py", line 783, in get_login_url
        raise web.HTTPError(403)
    tornado.web.HTTPError: HTTP 403: Forbidden
[W 2025-09-25 04:22:59.230 ServerApp] 403 GET /api/kernelspecs?1758756179216 (@172.16.33.3) 0.87ms referer=None
[W 2025-09-25 04:22:59.231 ServerApp] wrote error: 'Forbidden'
    Traceback (most recent call last):
      File "/home/s0214/.conda/envs/monster/lib/python3.8/site-packages/tornado/web.py", line 1788, in _execute
        result = method(*self.path_args, **self.path_kwargs)
      File "/home/s0214/.conda/envs/monster/lib/python3.8/site-packages/tornado/web.py", line 3289, in wrapper
        url = self.get_login_url()
      File "/home/s0214/.conda/envs/monster/lib/python3.8/site-packages/jupyter_server/base/handlers.py", line 783, in get_login_url
        raise web.HTTPError(403)
    tornado.web.HTTPError: HTTP 403: Forbidden
[W 2025-09-25 04:22:59.231 ServerApp] 403 GET /api/kernels?1758756179217 (@172.16.33.3) 1.04ms referer=None
[W 2025-09-25 04:22:59.231 ServerApp] wrote error: 'Forbidden'
    Traceback (most recent call last):
      File "/home/s0214/.conda/envs/monster/lib/python3.8/site-packages/tornado/web.py", line 1788, in _execute
        result = method(*self.path_args, **self.path_kwargs)
      File "/home/s0214/.conda/envs/monster/lib/python3.8/site-packages/tornado/web.py", line 3289, in wrapper
        url = self.get_login_url()
      File "/home/s0214/.conda/envs/monster/lib/python3.8/site-packages/jupyter_server/base/handlers.py", line 783, in get_login_url
        raise web.HTTPError(403)
    tornado.web.HTTPError: HTTP 403: Forbidden
[W 2025-09-25 04:22:59.232 ServerApp] 403 GET /api/kernels?1758756179219 (@172.16.33.3) 1.56ms referer=None
[W 2025-09-25 04:22:59.236 ServerApp] wrote error: 'Forbidden'
    Traceback (most recent call last):
      File "/home/s0214/.conda/envs/monster/lib/python3.8/site-packages/tornado/web.py", line 1788, in _execute
        result = method(*self.path_args, **self.path_kwargs)
      File "/home/s0214/.conda/envs/monster/lib/python3.8/site-packages/tornado/web.py", line 3289, in wrapper
        url = self.get_login_url()
      File "/home/s0214/.conda/envs/monster/lib/python3.8/site-packages/jupyter_server/base/handlers.py", line 783, in get_login_url
        raise web.HTTPError(403)
    tornado.web.HTTPError: HTTP 403: Forbidden
[W 2025-09-25 04:22:59.237 ServerApp] 403 GET /api/sessions?1758756179221 (@172.16.33.3) 1.02ms referer=None
[I 2025-09-25 04:22:59.245 JupyterNotebookApp] 302 GET /tree? (@172.16.33.3) 0.52ms
[I 2025-09-25 04:22:59.247 ServerApp] 302 GET / (@172.16.33.3) 0.67ms
[W 2025-09-25 04:22:59.247 ServerApp] wrote error: 'Forbidden'
    Traceback (most recent call last):
      File "/home/s0214/.conda/envs/monster/lib/python3.8/site-packages/tornado/web.py", line 1788, in _execute
        result = method(*self.path_args, **self.path_kwargs)
      File "/home/s0214/.conda/envs/monster/lib/python3.8/site-packages/tornado/web.py", line 3289, in wrapper
        url = self.get_login_url()
      File "/home/s0214/.conda/envs/monster/lib/python3.8/site-packages/jupyter_server/base/handlers.py", line 783, in get_login_url
        raise web.HTTPError(403)
    tornado.web.HTTPError: HTTP 403: Forbidden
[W 2025-09-25 04:22:59.247 ServerApp] 403 GET /api/kernelspecs?1758756179235 (@172.16.33.3) 1.04ms referer=None
[I 2025-09-25 04:22:59.285 JupyterNotebookApp] 302 GET /tree? (@172.16.33.3) 0.44ms
[W 2025-09-25 04:22:59.290 ServerApp] wrote error: 'Forbidden'
    Traceback (most recent call last):
      File "/home/s0214/.conda/envs/monster/lib/python3.8/site-packages/tornado/web.py", line 1788, in _execute
        result = method(*self.path_args, **self.path_kwargs)
      File "/home/s0214/.conda/envs/monster/lib/python3.8/site-packages/tornado/web.py", line 3289, in wrapper
        url = self.get_login_url()
      File "/home/s0214/.conda/envs/monster/lib/python3.8/site-packages/jupyter_server/base/handlers.py", line 783, in get_login_url
        raise web.HTTPError(403)
    tornado.web.HTTPError: HTTP 403: Forbidden
[W 2025-09-25 04:22:59.291 ServerApp] 403 GET /api/kernelspecs?1758756179286 (@172.16.33.3) 1.04ms referer=None
[W 2025-09-25 04:22:59.297 ServerApp] wrote error: 'Forbidden'
    Traceback (most recent call last):
      File "/home/s0214/.conda/envs/monster/lib/python3.8/site-packages/tornado/web.py", line 1788, in _execute
        result = method(*self.path_args, **self.path_kwargs)
      File "/home/s0214/.conda/envs/monster/lib/python3.8/site-packages/tornado/web.py", line 3289, in wrapper
        url = self.get_login_url()
      File "/home/s0214/.conda/envs/monster/lib/python3.8/site-packages/jupyter_server/base/handlers.py", line 783, in get_login_url
        raise web.HTTPError(403)
    tornado.web.HTTPError: HTTP 403: Forbidden
[W 2025-09-25 04:22:59.297 ServerApp] 403 GET /api/kernels?1758756179287 (@172.16.33.3) 1.16ms referer=None
[W 2025-09-25 04:22:59.299 ServerApp] wrote error: 'Forbidden'
    Traceback (most recent call last):
      File "/home/s0214/.conda/envs/monster/lib/python3.8/site-packages/tornado/web.py", line 1788, in _execute
        result = method(*self.path_args, **self.path_kwargs)
      File "/home/s0214/.conda/envs/monster/lib/python3.8/site-packages/tornado/web.py", line 3289, in wrapper
        url = self.get_login_url()
      File "/home/s0214/.conda/envs/monster/lib/python3.8/site-packages/jupyter_server/base/handlers.py", line 783, in get_login_url
        raise web.HTTPError(403)
    tornado.web.HTTPError: HTTP 403: Forbidden
[W 2025-09-25 04:22:59.300 ServerApp] 403 GET /api/kernels?1758756179289 (@172.16.33.3) 1.38ms referer=None
[W 2025-09-25 04:22:59.300 ServerApp] wrote error: 'Forbidden'
    Traceback (most recent call last):
      File "/home/s0214/.conda/envs/monster/lib/python3.8/site-packages/tornado/web.py", line 1788, in _execute
        result = method(*self.path_args, **self.path_kwargs)
      File "/home/s0214/.conda/envs/monster/lib/python3.8/site-packages/tornado/web.py", line 3289, in wrapper
        url = self.get_login_url()
      File "/home/s0214/.conda/envs/monster/lib/python3.8/site-packages/jupyter_server/base/handlers.py", line 783, in get_login_url
        raise web.HTTPError(403)
    tornado.web.HTTPError: HTTP 403: Forbidden
[W 2025-09-25 04:22:59.301 ServerApp] 403 GET /api/sessions?1758756179290 (@172.16.33.3) 1.82ms referer=None
[W 2025-09-25 04:22:59.301 ServerApp] wrote error: 'Forbidden'
    Traceback (most recent call last):
      File "/home/s0214/.conda/envs/monster/lib/python3.8/site-packages/tornado/web.py", line 1788, in _execute
        result = method(*self.path_args, **self.path_kwargs)
      File "/home/s0214/.conda/envs/monster/lib/python3.8/site-packages/tornado/web.py", line 3289, in wrapper
        url = self.get_login_url()
      File "/home/s0214/.conda/envs/monster/lib/python3.8/site-packages/jupyter_server/base/handlers.py", line 783, in get_login_url
        raise web.HTTPError(403)
    tornado.web.HTTPError: HTTP 403: Forbidden
[W 2025-09-25 04:22:59.301 ServerApp] 403 GET /api/kernelspecs?1758756179295 (@172.16.33.3) 2.19ms referer=None
[W 2025-09-25 04:22:59.302 ServerApp] wrote error: 'Forbidden'
    Traceback (most recent call last):
      File "/home/s0214/.conda/envs/monster/lib/python3.8/site-packages/tornado/web.py", line 1788, in _execute
        result = method(*self.path_args, **self.path_kwargs)
      File "/home/s0214/.conda/envs/monster/lib/python3.8/site-packages/tornado/web.py", line 3289, in wrapper
        url = self.get_login_url()
      File "/home/s0214/.conda/envs/monster/lib/python3.8/site-packages/jupyter_server/base/handlers.py", line 783, in get_login_url
        raise web.HTTPError(403)
    tornado.web.HTTPError: HTTP 403: Forbidden
[W 2025-09-25 04:22:59.302 ServerApp] 403 GET /api/kernelspecs?1758756179299 (@172.16.33.3) 0.75ms referer=None
[W 2025-09-25 04:22:59.309 ServerApp] wrote error: 'Forbidden'
    Traceback (most recent call last):
      File "/home/s0214/.conda/envs/monster/lib/python3.8/site-packages/tornado/web.py", line 1788, in _execute
        result = method(*self.path_args, **self.path_kwargs)
      File "/home/s0214/.conda/envs/monster/lib/python3.8/site-packages/tornado/web.py", line 3289, in wrapper
        url = self.get_login_url()
      File "/home/s0214/.conda/envs/monster/lib/python3.8/site-packages/jupyter_server/base/handlers.py", line 783, in get_login_url
        raise web.HTTPError(403)
    tornado.web.HTTPError: HTTP 403: Forbidden
[W 2025-09-25 04:22:59.310 ServerApp] 403 GET /api/kernels?1758756179300 (@172.16.33.3) 0.80ms referer=None
[W 2025-09-25 04:22:59.311 ServerApp] wrote error: 'Forbidden'
    Traceback (most recent call last):
      File "/home/s0214/.conda/envs/monster/lib/python3.8/site-packages/tornado/web.py", line 1788, in _execute
        result = method(*self.path_args, **self.path_kwargs)
      File "/home/s0214/.conda/envs/monster/lib/python3.8/site-packages/tornado/web.py", line 3289, in wrapper
        url = self.get_login_url()
      File "/home/s0214/.conda/envs/monster/lib/python3.8/site-packages/jupyter_server/base/handlers.py", line 783, in get_login_url
        raise web.HTTPError(403)
    tornado.web.HTTPError: HTTP 403: Forbidden
[W 2025-09-25 04:22:59.311 ServerApp] 403 GET /api/kernels?1758756179301 (@172.16.33.3) 1.13ms referer=None
[W 2025-09-25 04:22:59.312 ServerApp] wrote error: 'Forbidden'
    Traceback (most recent call last):
      File "/home/s0214/.conda/envs/monster/lib/python3.8/site-packages/tornado/web.py", line 1788, in _execute
        result = method(*self.path_args, **self.path_kwargs)
      File "/home/s0214/.conda/envs/monster/lib/python3.8/site-packages/tornado/web.py", line 3289, in wrapper
        url = self.get_login_url()
      File "/home/s0214/.conda/envs/monster/lib/python3.8/site-packages/jupyter_server/base/handlers.py", line 783, in get_login_url
        raise web.HTTPError(403)
    tornado.web.HTTPError: HTTP 403: Forbidden
[W 2025-09-25 04:22:59.312 ServerApp] 403 GET /api/kernelspecs?1758756179307 (@172.16.33.3) 1.90ms referer=None
[W 2025-09-25 04:22:59.312 ServerApp] wrote error: 'Forbidden'
    Traceback (most recent call last):
      File "/home/s0214/.conda/envs/monster/lib/python3.8/site-packages/tornado/web.py", line 1788, in _execute
        result = method(*self.path_args, **self.path_kwargs)
      File "/home/s0214/.conda/envs/monster/lib/python3.8/site-packages/tornado/web.py", line 3289, in wrapper
        url = self.get_login_url()
      File "/home/s0214/.conda/envs/monster/lib/python3.8/site-packages/jupyter_server/base/handlers.py", line 783, in get_login_url
        raise web.HTTPError(403)
    tornado.web.HTTPError: HTTP 403: Forbidden
[W 2025-09-25 04:22:59.313 ServerApp] 403 GET /api/sessions?1758756179302 (@172.16.33.3) 1.62ms referer=None
[I 2025-09-25 04:22:59.313 ServerApp] 302 GET / (@172.16.33.3) 1.62ms
[I 2025-09-25 04:22:59.317 JupyterNotebookApp] 302 GET /tree? (@172.16.33.3) 0.45ms
[W 2025-09-25 04:22:59.323 ServerApp] wrote error: 'Forbidden'
    Traceback (most recent call last):
      File "/home/s0214/.conda/envs/monster/lib/python3.8/site-packages/tornado/web.py", line 1788, in _execute
        result = method(*self.path_args, **self.path_kwargs)
      File "/home/s0214/.conda/envs/monster/lib/python3.8/site-packages/tornado/web.py", line 3289, in wrapper
        url = self.get_login_url()
      File "/home/s0214/.conda/envs/monster/lib/python3.8/site-packages/jupyter_server/base/handlers.py", line 783, in get_login_url
        raise web.HTTPError(403)
    tornado.web.HTTPError: HTTP 403: Forbidden
[W 2025-09-25 04:22:59.324 ServerApp] 403 GET /api/kernelspecs?1758756179320 (@172.16.33.3) 0.74ms referer=None
[W 2025-09-25 04:22:59.328 ServerApp] wrote error: 'Forbidden'
    Traceback (most recent call last):
      File "/home/s0214/.conda/envs/monster/lib/python3.8/site-packages/tornado/web.py", line 1788, in _execute
        result = method(*self.path_args, **self.path_kwargs)
      File "/home/s0214/.conda/envs/monster/lib/python3.8/site-packages/tornado/web.py", line 3289, in wrapper
        url = self.get_login_url()
      File "/home/s0214/.conda/envs/monster/lib/python3.8/site-packages/jupyter_server/base/handlers.py", line 783, in get_login_url
        raise web.HTTPError(403)
    tornado.web.HTTPError: HTTP 403: Forbidden
[W 2025-09-25 04:22:59.328 ServerApp] 403 GET /api/kernels?1758756179321 (@172.16.33.3) 0.93ms referer=None
[W 2025-09-25 04:22:59.328 ServerApp] wrote error: 'Forbidden'
    Traceback (most recent call last):
      File "/home/s0214/.conda/envs/monster/lib/python3.8/site-packages/tornado/web.py", line 1788, in _execute
        result = method(*self.path_args, **self.path_kwargs)
      File "/home/s0214/.conda/envs/monster/lib/python3.8/site-packages/tornado/web.py", line 3289, in wrapper
        url = self.get_login_url()
      File "/home/s0214/.conda/envs/monster/lib/python3.8/site-packages/jupyter_server/base/handlers.py", line 783, in get_login_url
        raise web.HTTPError(403)
    tornado.web.HTTPError: HTTP 403: Forbidden
[W 2025-09-25 04:22:59.329 ServerApp] 403 GET /api/kernels?1758756179323 (@172.16.33.3) 1.36ms referer=None
[W 2025-09-25 04:22:59.332 ServerApp] wrote error: 'Forbidden'
    Traceback (most recent call last):
      File "/home/s0214/.conda/envs/monster/lib/python3.8/site-packages/tornado/web.py", line 1788, in _execute
        result = method(*self.path_args, **self.path_kwargs)
      File "/home/s0214/.conda/envs/monster/lib/python3.8/site-packages/tornado/web.py", line 3289, in wrapper
        url = self.get_login_url()
      File "/home/s0214/.conda/envs/monster/lib/python3.8/site-packages/jupyter_server/base/handlers.py", line 783, in get_login_url
        raise web.HTTPError(403)
    tornado.web.HTTPError: HTTP 403: Forbidden
[W 2025-09-25 04:22:59.333 ServerApp] 403 GET /api/sessions?1758756179324 (@172.16.33.3) 1.04ms referer=None
[W 2025-09-25 04:22:59.333 ServerApp] wrote error: 'Forbidden'
    Traceback (most recent call last):
      File "/home/s0214/.conda/envs/monster/lib/python3.8/site-packages/tornado/web.py", line 1788, in _execute
        result = method(*self.path_args, **self.path_kwargs)
      File "/home/s0214/.conda/envs/monster/lib/python3.8/site-packages/tornado/web.py", line 3289, in wrapper
        url = self.get_login_url()
      File "/home/s0214/.conda/envs/monster/lib/python3.8/site-packages/jupyter_server/base/handlers.py", line 783, in get_login_url
        raise web.HTTPError(403)
    tornado.web.HTTPError: HTTP 403: Forbidden
[W 2025-09-25 04:22:59.334 ServerApp] 403 GET /api/kernelspecs?1758756179326 (@172.16.33.3) 0.74ms referer=None
[I 2025-09-25 04:24:49.382 ServerApp] 302 GET / (@172.16.33.3) 0.56ms
[I 2025-09-25 04:24:49.386 JupyterNotebookApp] 302 GET /tree? (@172.16.33.3) 0.59ms
[I 2025-09-25 04:24:51.444 ServerApp] 302 GET / (@172.16.33.3) 0.35ms
[I 2025-09-25 04:24:51.447 JupyterNotebookApp] 302 GET /tree? (@172.16.33.3) 0.47ms
[I 2025-09-25 04:24:59.279 ServerApp] 302 GET / (@172.16.33.3) 0.41ms
[I 2025-09-25 04:24:59.283 JupyterNotebookApp] 302 GET /tree? (@172.16.33.3) 0.47ms
[I 2025-09-25 04:24:59.363 ServerApp] Kernel started: 9c06c580-1f97-4615-a835-3155a460af2c
[IPKernelApp] ERROR | Failed to create history session in /misc/home4/s0214/.ipython/profile_default/history.sqlite. History will not be saved.
Traceback (most recent call last):
  File "/home/s0214/.conda/envs/monster/lib/python3.8/site-packages/IPython/core/history.py", line 543, in __init__
    self.new_session()
  File "<decorator-gen-15>", line 2, in new_session
  File "/home/s0214/.conda/envs/monster/lib/python3.8/site-packages/IPython/core/history.py", line 58, in needs_sqlite
    return f(self, *a, **kw)
  File "/home/s0214/.conda/envs/monster/lib/python3.8/site-packages/IPython/core/history.py", line 568, in new_session
    cur = conn.execute("""INSERT INTO sessions VALUES (NULL, ?, NULL,
sqlite3.OperationalError: unable to open database file
[I 2025-09-25 04:25:00.451 ServerApp] Connecting to kernel 9c06c580-1f97-4615-a835-3155a460af2c.
[I 2025-09-25 04:25:00.642 ServerApp] 302 GET / (@172.16.33.3) 0.65ms
[I 2025-09-25 04:25:00.644 ServerApp] 302 GET / (@172.16.33.3) 1.19ms
[I 2025-09-25 04:25:00.658 JupyterNotebookApp] 302 GET /tree? (@172.16.33.3) 0.63ms
[I 2025-09-25 04:25:00.662 JupyterNotebookApp] 302 GET /tree? (@172.16.33.3) 3.43ms
[W 2025-09-25 04:25:00.679 ServerApp] wrote error: 'Forbidden'
    Traceback (most recent call last):
      File "/home/s0214/.conda/envs/monster/lib/python3.8/site-packages/tornado/web.py", line 1788, in _execute
        result = method(*self.path_args, **self.path_kwargs)
      File "/home/s0214/.conda/envs/monster/lib/python3.8/site-packages/tornado/web.py", line 3289, in wrapper
        url = self.get_login_url()
      File "/home/s0214/.conda/envs/monster/lib/python3.8/site-packages/jupyter_server/base/handlers.py", line 783, in get_login_url
        raise web.HTTPError(403)
    tornado.web.HTTPError: HTTP 403: Forbidden
[W 2025-09-25 04:25:00.680 ServerApp] 403 GET /api/kernelspecs?1758756300676 (@172.16.33.3) 1.70ms referer=None
[W 2025-09-25 04:25:00.682 ServerApp] wrote error: 'Forbidden'
    Traceback (most recent call last):
      File "/home/s0214/.conda/envs/monster/lib/python3.8/site-packages/tornado/web.py", line 1788, in _execute
        result = method(*self.path_args, **self.path_kwargs)
      File "/home/s0214/.conda/envs/monster/lib/python3.8/site-packages/tornado/web.py", line 3289, in wrapper
        url = self.get_login_url()
      File "/home/s0214/.conda/envs/monster/lib/python3.8/site-packages/jupyter_server/base/handlers.py", line 783, in get_login_url
        raise web.HTTPError(403)
    tornado.web.HTTPError: HTTP 403: Forbidden
[W 2025-09-25 04:25:00.683 ServerApp] 403 GET /api/kernelspecs?1758756300679 (@172.16.33.3) 1.02ms referer=None
[W 2025-09-25 04:25:00.689 ServerApp] wrote error: 'Forbidden'
    Traceback (most recent call last):
      File "/home/s0214/.conda/envs/monster/lib/python3.8/site-packages/tornado/web.py", line 1788, in _execute
        result = method(*self.path_args, **self.path_kwargs)
      File "/home/s0214/.conda/envs/monster/lib/python3.8/site-packages/tornado/web.py", line 3289, in wrapper
        url = self.get_login_url()
      File "/home/s0214/.conda/envs/monster/lib/python3.8/site-packages/jupyter_server/base/handlers.py", line 783, in get_login_url
        raise web.HTTPError(403)
    tornado.web.HTTPError: HTTP 403: Forbidden
[W 2025-09-25 04:25:00.689 ServerApp] 403 GET /api/kernels?1758756300676 (@172.16.33.3) 1.01ms referer=None
[W 2025-09-25 04:25:00.693 ServerApp] wrote error: 'Forbidden'
    Traceback (most recent call last):
      File "/home/s0214/.conda/envs/monster/lib/python3.8/site-packages/tornado/web.py", line 1788, in _execute
        result = method(*self.path_args, **self.path_kwargs)
      File "/home/s0214/.conda/envs/monster/lib/python3.8/site-packages/tornado/web.py", line 3289, in wrapper
        url = self.get_login_url()
      File "/home/s0214/.conda/envs/monster/lib/python3.8/site-packages/jupyter_server/base/handlers.py", line 783, in get_login_url
        raise web.HTTPError(403)
    tornado.web.HTTPError: HTTP 403: Forbidden
[W 2025-09-25 04:25:00.694 ServerApp] 403 GET /api/kernels?1758756300680 (@172.16.33.3) 1.09ms referer=None
[W 2025-09-25 04:25:00.695 ServerApp] wrote error: 'Forbidden'
    Traceback (most recent call last):
      File "/home/s0214/.conda/envs/monster/lib/python3.8/site-packages/tornado/web.py", line 1788, in _execute
        result = method(*self.path_args, **self.path_kwargs)
      File "/home/s0214/.conda/envs/monster/lib/python3.8/site-packages/tornado/web.py", line 3289, in wrapper
        url = self.get_login_url()
      File "/home/s0214/.conda/envs/monster/lib/python3.8/site-packages/jupyter_server/base/handlers.py", line 783, in get_login_url
        raise web.HTTPError(403)
    tornado.web.HTTPError: HTTP 403: Forbidden
[W 2025-09-25 04:25:00.696 ServerApp] 403 GET /api/kernels?1758756300682 (@172.16.33.3) 1.67ms referer=None
[W 2025-09-25 04:25:00.697 ServerApp] wrote error: 'Forbidden'
    Traceback (most recent call last):
      File "/home/s0214/.conda/envs/monster/lib/python3.8/site-packages/tornado/web.py", line 1788, in _execute
        result = method(*self.path_args, **self.path_kwargs)
      File "/home/s0214/.conda/envs/monster/lib/python3.8/site-packages/tornado/web.py", line 3289, in wrapper
        url = self.get_login_url()
      File "/home/s0214/.conda/envs/monster/lib/python3.8/site-packages/jupyter_server/base/handlers.py", line 783, in get_login_url
        raise web.HTTPError(403)
    tornado.web.HTTPError: HTTP 403: Forbidden
[W 2025-09-25 04:25:00.698 ServerApp] 403 GET /api/kernelspecs?1758756300689 (@172.16.33.3) 2.77ms referer=None
[W 2025-09-25 04:25:00.698 ServerApp] wrote error: 'Forbidden'
    Traceback (most recent call last):
      File "/home/s0214/.conda/envs/monster/lib/python3.8/site-packages/tornado/web.py", line 1788, in _execute
        result = method(*self.path_args, **self.path_kwargs)
      File "/home/s0214/.conda/envs/monster/lib/python3.8/site-packages/tornado/web.py", line 3289, in wrapper
        url = self.get_login_url()
      File "/home/s0214/.conda/envs/monster/lib/python3.8/site-packages/jupyter_server/base/handlers.py", line 783, in get_login_url
        raise web.HTTPError(403)
    tornado.web.HTTPError: HTTP 403: Forbidden
[W 2025-09-25 04:25:00.699 ServerApp] 403 GET /api/sessions?1758756300683 (@172.16.33.3) 2.29ms referer=None
[W 2025-09-25 04:25:00.699 ServerApp] wrote error: 'Forbidden'
    Traceback (most recent call last):
      File "/home/s0214/.conda/envs/monster/lib/python3.8/site-packages/tornado/web.py", line 1788, in _execute
        result = method(*self.path_args, **self.path_kwargs)
      File "/home/s0214/.conda/envs/monster/lib/python3.8/site-packages/tornado/web.py", line 3289, in wrapper
        url = self.get_login_url()
      File "/home/s0214/.conda/envs/monster/lib/python3.8/site-packages/jupyter_server/base/handlers.py", line 783, in get_login_url
        raise web.HTTPError(403)
    tornado.web.HTTPError: HTTP 403: Forbidden
[W 2025-09-25 04:25:00.699 ServerApp] 403 GET /api/kernels?1758756300684 (@172.16.33.3) 2.80ms referer=None
[W 2025-09-25 04:25:00.701 ServerApp] wrote error: 'Forbidden'
    Traceback (most recent call last):
      File "/home/s0214/.conda/envs/monster/lib/python3.8/site-packages/tornado/web.py", line 1788, in _execute
        result = method(*self.path_args, **self.path_kwargs)
      File "/home/s0214/.conda/envs/monster/lib/python3.8/site-packages/tornado/web.py", line 3289, in wrapper
        url = self.get_login_url()
      File "/home/s0214/.conda/envs/monster/lib/python3.8/site-packages/jupyter_server/base/handlers.py", line 783, in get_login_url
        raise web.HTTPError(403)
    tornado.web.HTTPError: HTTP 403: Forbidden
[W 2025-09-25 04:25:00.701 ServerApp] 403 GET /api/sessions?1758756300686 (@172.16.33.3) 1.47ms referer=None
[W 2025-09-25 04:25:00.702 ServerApp] wrote error: 'Forbidden'
    Traceback (most recent call last):
      File "/home/s0214/.conda/envs/monster/lib/python3.8/site-packages/tornado/web.py", line 1788, in _execute
        result = method(*self.path_args, **self.path_kwargs)
      File "/home/s0214/.conda/envs/monster/lib/python3.8/site-packages/tornado/web.py", line 3289, in wrapper
        url = self.get_login_url()
      File "/home/s0214/.conda/envs/monster/lib/python3.8/site-packages/jupyter_server/base/handlers.py", line 783, in get_login_url
        raise web.HTTPError(403)
    tornado.web.HTTPError: HTTP 403: Forbidden
[W 2025-09-25 04:25:00.702 ServerApp] 403 GET /api/kernelspecs?1758756300688 (@172.16.33.3) 2.02ms referer=None
[I 2025-09-25 04:25:00.704 ServerApp] 302 GET / (@172.16.33.3) 0.44ms
[I 2025-09-25 04:25:00.705 ServerApp] 302 GET / (@172.16.33.3) 0.43ms
[I 2025-09-25 04:25:00.707 JupyterNotebookApp] 302 GET /tree? (@172.16.33.3) 0.71ms
[I 2025-09-25 04:25:00.710 JupyterNotebookApp] 302 GET /tree? (@172.16.33.3) 1.07ms
[W 2025-09-25 04:25:00.717 ServerApp] wrote error: 'Forbidden'
    Traceback (most recent call last):
      File "/home/s0214/.conda/envs/monster/lib/python3.8/site-packages/tornado/web.py", line 1788, in _execute
        result = method(*self.path_args, **self.path_kwargs)
      File "/home/s0214/.conda/envs/monster/lib/python3.8/site-packages/tornado/web.py", line 3289, in wrapper
        url = self.get_login_url()
      File "/home/s0214/.conda/envs/monster/lib/python3.8/site-packages/jupyter_server/base/handlers.py", line 783, in get_login_url
        raise web.HTTPError(403)
    tornado.web.HTTPError: HTTP 403: Forbidden
[W 2025-09-25 04:25:00.717 ServerApp] 403 GET /api/kernelspecs?1758756300713 (@172.16.33.3) 1.02ms referer=None
[W 2025-09-25 04:25:00.721 ServerApp] wrote error: 'Forbidden'
    Traceback (most recent call last):
      File "/home/s0214/.conda/envs/monster/lib/python3.8/site-packages/tornado/web.py", line 1788, in _execute
        result = method(*self.path_args, **self.path_kwargs)
      File "/home/s0214/.conda/envs/monster/lib/python3.8/site-packages/tornado/web.py", line 3289, in wrapper
        url = self.get_login_url()
      File "/home/s0214/.conda/envs/monster/lib/python3.8/site-packages/jupyter_server/base/handlers.py", line 783, in get_login_url
        raise web.HTTPError(403)
    tornado.web.HTTPError: HTTP 403: Forbidden
[W 2025-09-25 04:25:00.722 ServerApp] 403 GET /api/kernels?1758756300716 (@172.16.33.3) 1.85ms referer=None
[W 2025-09-25 04:25:00.722 ServerApp] wrote error: 'Forbidden'
    Traceback (most recent call last):
      File "/home/s0214/.conda/envs/monster/lib/python3.8/site-packages/tornado/web.py", line 1788, in _execute
        result = method(*self.path_args, **self.path_kwargs)
      File "/home/s0214/.conda/envs/monster/lib/python3.8/site-packages/tornado/web.py", line 3289, in wrapper
        url = self.get_login_url()
      File "/home/s0214/.conda/envs/monster/lib/python3.8/site-packages/jupyter_server/base/handlers.py", line 783, in get_login_url
        raise web.HTTPError(403)
    tornado.web.HTTPError: HTTP 403: Forbidden
[W 2025-09-25 04:25:00.723 ServerApp] 403 GET /api/sessions?1758756300717 (@172.16.33.3) 2.24ms referer=None
[W 2025-09-25 04:25:00.723 ServerApp] wrote error: 'Forbidden'
    Traceback (most recent call last):
      File "/home/s0214/.conda/envs/monster/lib/python3.8/site-packages/tornado/web.py", line 1788, in _execute
        result = method(*self.path_args, **self.path_kwargs)
      File "/home/s0214/.conda/envs/monster/lib/python3.8/site-packages/tornado/web.py", line 3289, in wrapper
        url = self.get_login_url()
      File "/home/s0214/.conda/envs/monster/lib/python3.8/site-packages/jupyter_server/base/handlers.py", line 783, in get_login_url
        raise web.HTTPError(403)
    tornado.web.HTTPError: HTTP 403: Forbidden
[W 2025-09-25 04:25:00.724 ServerApp] 403 GET /api/kernels?1758756300714 (@172.16.33.3) 2.76ms referer=None
[W 2025-09-25 04:25:00.725 ServerApp] wrote error: 'Forbidden'
    Traceback (most recent call last):
      File "/home/s0214/.conda/envs/monster/lib/python3.8/site-packages/tornado/web.py", line 1788, in _execute
        result = method(*self.path_args, **self.path_kwargs)
      File "/home/s0214/.conda/envs/monster/lib/python3.8/site-packages/tornado/web.py", line 3289, in wrapper
        url = self.get_login_url()
      File "/home/s0214/.conda/envs/monster/lib/python3.8/site-packages/jupyter_server/base/handlers.py", line 783, in get_login_url
        raise web.HTTPError(403)
    tornado.web.HTTPError: HTTP 403: Forbidden
[W 2025-09-25 04:25:00.725 ServerApp] 403 GET /api/kernelspecs?1758756300720 (@172.16.33.3) 1.00ms referer=None
[W 2025-09-25 04:25:00.732 ServerApp] wrote error: 'Forbidden'
    Traceback (most recent call last):
      File "/home/s0214/.conda/envs/monster/lib/python3.8/site-packages/tornado/web.py", line 1788, in _execute
        result = method(*self.path_args, **self.path_kwargs)
      File "/home/s0214/.conda/envs/monster/lib/python3.8/site-packages/tornado/web.py", line 3289, in wrapper
        url = self.get_login_url()
      File "/home/s0214/.conda/envs/monster/lib/python3.8/site-packages/jupyter_server/base/handlers.py", line 783, in get_login_url
        raise web.HTTPError(403)
    tornado.web.HTTPError: HTTP 403: Forbidden
[W 2025-09-25 04:25:00.733 ServerApp] 403 GET /api/kernels?1758756300721 (@172.16.33.3) 1.10ms referer=None
[W 2025-09-25 04:25:00.734 ServerApp] wrote error: 'Forbidden'
    Traceback (most recent call last):
      File "/home/s0214/.conda/envs/monster/lib/python3.8/site-packages/tornado/web.py", line 1788, in _execute
        result = method(*self.path_args, **self.path_kwargs)
      File "/home/s0214/.conda/envs/monster/lib/python3.8/site-packages/tornado/web.py", line 3289, in wrapper
        url = self.get_login_url()
      File "/home/s0214/.conda/envs/monster/lib/python3.8/site-packages/jupyter_server/base/handlers.py", line 783, in get_login_url
        raise web.HTTPError(403)
    tornado.web.HTTPError: HTTP 403: Forbidden
[W 2025-09-25 04:25:00.734 ServerApp] 403 GET /api/kernelspecs?1758756300722 (@172.16.33.3) 1.22ms referer=None
[W 2025-09-25 04:25:00.736 ServerApp] wrote error: 'Forbidden'
    Traceback (most recent call last):
      File "/home/s0214/.conda/envs/monster/lib/python3.8/site-packages/tornado/web.py", line 1788, in _execute
        result = method(*self.path_args, **self.path_kwargs)
      File "/home/s0214/.conda/envs/monster/lib/python3.8/site-packages/tornado/web.py", line 3289, in wrapper
        url = self.get_login_url()
      File "/home/s0214/.conda/envs/monster/lib/python3.8/site-packages/jupyter_server/base/handlers.py", line 783, in get_login_url
        raise web.HTTPError(403)
    tornado.web.HTTPError: HTTP 403: Forbidden
[W 2025-09-25 04:25:00.736 ServerApp] 403 GET /api/kernels?1758756300723 (@172.16.33.3) 1.58ms referer=None
[W 2025-09-25 04:25:00.737 ServerApp] wrote error: 'Forbidden'
    Traceback (most recent call last):
      File "/home/s0214/.conda/envs/monster/lib/python3.8/site-packages/tornado/web.py", line 1788, in _execute
        result = method(*self.path_args, **self.path_kwargs)
      File "/home/s0214/.conda/envs/monster/lib/python3.8/site-packages/tornado/web.py", line 3289, in wrapper
        url = self.get_login_url()
      File "/home/s0214/.conda/envs/monster/lib/python3.8/site-packages/jupyter_server/base/handlers.py", line 783, in get_login_url
        raise web.HTTPError(403)
    tornado.web.HTTPError: HTTP 403: Forbidden
[W 2025-09-25 04:25:00.737 ServerApp] 403 GET /api/kernelspecs?1758756300730 (@172.16.33.3) 2.34ms referer=None
[W 2025-09-25 04:25:00.738 ServerApp] wrote error: 'Forbidden'
    Traceback (most recent call last):
      File "/home/s0214/.conda/envs/monster/lib/python3.8/site-packages/tornado/web.py", line 1788, in _execute
        result = method(*self.path_args, **self.path_kwargs)
      File "/home/s0214/.conda/envs/monster/lib/python3.8/site-packages/tornado/web.py", line 3289, in wrapper
        url = self.get_login_url()
      File "/home/s0214/.conda/envs/monster/lib/python3.8/site-packages/jupyter_server/base/handlers.py", line 783, in get_login_url
        raise web.HTTPError(403)
    tornado.web.HTTPError: HTTP 403: Forbidden
[W 2025-09-25 04:25:00.738 ServerApp] 403 GET /api/sessions?1758756300725 (@172.16.33.3) 1.98ms referer=None
slurmstepd: error: *** JOB 19578796 ON tesla-v100 CANCELLED AT 2025-09-25T05:23:00 DUE TO TIME LIMIT ***
