Both `sys_prefix` and `user` level settings are read-only, cannot auto-migrate `disabledExtensions` to `lockedExtensions`
[I 2025-10-05 20:29:43.310 ServerApp] jupyter_lsp | extension was successfully linked.
[I 2025-10-05 20:29:43.316 ServerApp] jupyter_server_terminals | extension was successfully linked.
[I 2025-10-05 20:29:43.321 ServerApp] jupyterlab | extension was successfully linked.
[I 2025-10-05 20:29:43.326 ServerApp] notebook | extension was successfully linked.
[I 2025-10-05 20:29:43.839 ServerApp] notebook_shim | extension was successfully linked.
[I 2025-10-05 20:29:43.899 ServerApp] notebook_shim | extension was successfully loaded.
[I 2025-10-05 20:29:43.901 ServerApp] jupyter_lsp | extension was successfully loaded.
[I 2025-10-05 20:29:43.904 ServerApp] jupyter_server_terminals | extension was successfully loaded.
[I 2025-10-05 20:29:43.912 LabApp] JupyterLab extension loaded from /home/s0214/.conda/envs/monster/lib/python3.8/site-packages/jupyterlab
[I 2025-10-05 20:29:43.912 LabApp] JupyterLab application directory is /misc/home4/s0214/.conda/envs/monster/share/jupyter/lab
[I 2025-10-05 20:29:43.913 LabApp] Extension Manager is 'pypi'.
[I 2025-10-05 20:29:43.998 ServerApp] jupyterlab | extension was successfully loaded.
[I 2025-10-05 20:29:44.006 ServerApp] notebook | extension was successfully loaded.
[I 2025-10-05 20:29:44.006 ServerApp] Serving notebooks from local directory: /misc/home6/s0214/MonSter
[I 2025-10-05 20:29:44.006 ServerApp] Jupyter Server 2.14.2 is running at:
[I 2025-10-05 20:29:44.006 ServerApp] http://tesla-v100:8888/tree?token=ba68f69d92d9503d105c24d8ac4c4f50b82d4aa14bd273a2
[I 2025-10-05 20:29:44.006 ServerApp]     http://127.0.0.1:8888/tree?token=ba68f69d92d9503d105c24d8ac4c4f50b82d4aa14bd273a2
[I 2025-10-05 20:29:44.007 ServerApp] Use Control-C to stop this server and shut down all kernels (twice to skip confirmation).
[C 2025-10-05 20:29:44.030 ServerApp] 
    
    To access the server, open this file in a browser:
        file:///misc/home4/s0214/.local/share/jupyter/runtime/jpserver-2517402-open.html
    Or copy and paste one of these URLs:
        http://tesla-v100:8888/tree?token=ba68f69d92d9503d105c24d8ac4c4f50b82d4aa14bd273a2
        http://127.0.0.1:8888/tree?token=ba68f69d92d9503d105c24d8ac4c4f50b82d4aa14bd273a2
[I 2025-10-05 20:29:44.161 ServerApp] Skipped non-installed server(s): basedpyright, bash-language-server, dockerfile-language-server-nodejs, javascript-typescript-langserver, jedi-language-server, julia-language-server, pyrefly, pyright, python-language-server, python-lsp-server, r-languageserver, sql-language-server, texlab, typescript-language-server, unified-language-server, vscode-css-languageserver-bin, vscode-html-languageserver-bin, vscode-json-languageserver-bin, yaml-language-server
[I 2025-10-05 20:30:56.521 ServerApp] 302 GET / (@172.16.33.3) 0.58ms
[I 2025-10-05 20:30:56.527 JupyterNotebookApp] 302 GET /tree? (@172.16.33.3) 0.69ms
[I 2025-10-05 20:30:57.735 ServerApp] 302 GET / (@172.16.33.3) 0.44ms
[I 2025-10-05 20:30:57.739 JupyterNotebookApp] 302 GET /tree? (@172.16.33.3) 0.59ms
[I 2025-10-05 20:31:11.660 ServerApp] 302 GET / (@172.16.33.3) 0.36ms
[I 2025-10-05 20:31:11.665 JupyterNotebookApp] 302 GET /tree? (@172.16.33.3) 0.76ms
[I 2025-10-05 20:31:11.747 ServerApp] Kernel started: 55f944ea-b59c-4ea2-a5b5-85ec9ebdbc53
[IPKernelApp] ERROR | Failed to create history session in /misc/home4/s0214/.ipython/profile_default/history.sqlite. History will not be saved.
Traceback (most recent call last):
  File "/home/s0214/.conda/envs/monster/lib/python3.8/site-packages/IPython/core/history.py", line 543, in __init__
    self.new_session()
  File "<decorator-gen-15>", line 2, in new_session
  File "/home/s0214/.conda/envs/monster/lib/python3.8/site-packages/IPython/core/history.py", line 58, in needs_sqlite
    return f(self, *a, **kw)
  File "/home/s0214/.conda/envs/monster/lib/python3.8/site-packages/IPython/core/history.py", line 568, in new_session
    cur = conn.execute("""INSERT INTO sessions VALUES (NULL, ?, NULL,
sqlite3.OperationalError: unable to open database file
[I 2025-10-05 20:31:12.811 ServerApp] Connecting to kernel 55f944ea-b59c-4ea2-a5b5-85ec9ebdbc53.
[I 2025-10-05 20:31:13.061 ServerApp] 302 GET / (@172.16.33.3) 2.40ms
[I 2025-10-05 20:31:13.062 ServerApp] 302 GET / (@172.16.33.3) 2.24ms
[I 2025-10-05 20:31:13.066 ServerApp] 302 GET / (@172.16.33.3) 2.98ms
[I 2025-10-05 20:31:13.067 ServerApp] 302 GET / (@172.16.33.3) 1.03ms
[I 2025-10-05 20:31:13.089 JupyterNotebookApp] 302 GET /tree? (@172.16.33.3) 0.69ms
[I 2025-10-05 20:31:13.090 JupyterNotebookApp] 302 GET /tree? (@172.16.33.3) 0.77ms
[I 2025-10-05 20:31:13.091 JupyterNotebookApp] 302 GET /tree? (@172.16.33.3) 0.77ms
[I 2025-10-05 20:31:13.095 JupyterNotebookApp] 302 GET /tree? (@172.16.33.3) 2.95ms
[W 2025-10-05 20:31:13.118 ServerApp] wrote error: 'Forbidden'
    Traceback (most recent call last):
      File "/home/s0214/.conda/envs/monster/lib/python3.8/site-packages/tornado/web.py", line 1788, in _execute
        result = method(*self.path_args, **self.path_kwargs)
      File "/home/s0214/.conda/envs/monster/lib/python3.8/site-packages/tornado/web.py", line 3289, in wrapper
        url = self.get_login_url()
      File "/home/s0214/.conda/envs/monster/lib/python3.8/site-packages/jupyter_server/base/handlers.py", line 783, in get_login_url
        raise web.HTTPError(403)
    tornado.web.HTTPError: HTTP 403: Forbidden
[W 2025-10-05 20:31:13.121 ServerApp] 403 GET /api/kernelspecs?1759678273114 (@172.16.33.3) 3.35ms referer=None
[W 2025-10-05 20:31:13.125 ServerApp] wrote error: 'Forbidden'
    Traceback (most recent call last):
      File "/home/s0214/.conda/envs/monster/lib/python3.8/site-packages/tornado/web.py", line 1788, in _execute
        result = method(*self.path_args, **self.path_kwargs)
      File "/home/s0214/.conda/envs/monster/lib/python3.8/site-packages/tornado/web.py", line 3289, in wrapper
        url = self.get_login_url()
      File "/home/s0214/.conda/envs/monster/lib/python3.8/site-packages/jupyter_server/base/handlers.py", line 783, in get_login_url
        raise web.HTTPError(403)
    tornado.web.HTTPError: HTTP 403: Forbidden
[W 2025-10-05 20:31:13.126 ServerApp] 403 GET /api/kernelspecs?1759678273121 (@172.16.33.3) 1.02ms referer=None
[W 2025-10-05 20:31:13.128 ServerApp] wrote error: 'Forbidden'
    Traceback (most recent call last):
      File "/home/s0214/.conda/envs/monster/lib/python3.8/site-packages/tornado/web.py", line 1788, in _execute
        result = method(*self.path_args, **self.path_kwargs)
      File "/home/s0214/.conda/envs/monster/lib/python3.8/site-packages/tornado/web.py", line 3289, in wrapper
        url = self.get_login_url()
      File "/home/s0214/.conda/envs/monster/lib/python3.8/site-packages/jupyter_server/base/handlers.py", line 783, in get_login_url
        raise web.HTTPError(403)
    tornado.web.HTTPError: HTTP 403: Forbidden
[W 2025-10-05 20:31:13.129 ServerApp] 403 GET /api/kernelspecs?1759678273125 (@172.16.33.3) 0.99ms referer=None
[W 2025-10-05 20:31:13.132 ServerApp] wrote error: 'Forbidden'
    Traceback (most recent call last):
      File "/home/s0214/.conda/envs/monster/lib/python3.8/site-packages/tornado/web.py", line 1788, in _execute
        result = method(*self.path_args, **self.path_kwargs)
      File "/home/s0214/.conda/envs/monster/lib/python3.8/site-packages/tornado/web.py", line 3289, in wrapper
        url = self.get_login_url()
      File "/home/s0214/.conda/envs/monster/lib/python3.8/site-packages/jupyter_server/base/handlers.py", line 783, in get_login_url
        raise web.HTTPError(403)
    tornado.web.HTTPError: HTTP 403: Forbidden
[W 2025-10-05 20:31:13.132 ServerApp] 403 GET /api/kernelspecs?1759678273128 (@172.16.33.3) 0.98ms referer=None
[W 2025-10-05 20:31:13.144 ServerApp] wrote error: 'Forbidden'
    Traceback (most recent call last):
      File "/home/s0214/.conda/envs/monster/lib/python3.8/site-packages/tornado/web.py", line 1788, in _execute
        result = method(*self.path_args, **self.path_kwargs)
      File "/home/s0214/.conda/envs/monster/lib/python3.8/site-packages/tornado/web.py", line 3289, in wrapper
        url = self.get_login_url()
      File "/home/s0214/.conda/envs/monster/lib/python3.8/site-packages/jupyter_server/base/handlers.py", line 783, in get_login_url
        raise web.HTTPError(403)
    tornado.web.HTTPError: HTTP 403: Forbidden
[W 2025-10-05 20:31:13.144 ServerApp] 403 GET /api/kernels?1759678273115 (@172.16.33.3) 1.07ms referer=None
[W 2025-10-05 20:31:13.145 ServerApp] wrote error: 'Forbidden'
    Traceback (most recent call last):
      File "/home/s0214/.conda/envs/monster/lib/python3.8/site-packages/tornado/web.py", line 1788, in _execute
        result = method(*self.path_args, **self.path_kwargs)
      File "/home/s0214/.conda/envs/monster/lib/python3.8/site-packages/tornado/web.py", line 3289, in wrapper
        url = self.get_login_url()
      File "/home/s0214/.conda/envs/monster/lib/python3.8/site-packages/jupyter_server/base/handlers.py", line 783, in get_login_url
        raise web.HTTPError(403)
    tornado.web.HTTPError: HTTP 403: Forbidden
[W 2025-10-05 20:31:13.146 ServerApp] 403 GET /api/kernels?1759678273117 (@172.16.33.3) 1.04ms referer=None
[W 2025-10-05 20:31:13.151 ServerApp] wrote error: 'Forbidden'
    Traceback (most recent call last):
      File "/home/s0214/.conda/envs/monster/lib/python3.8/site-packages/tornado/web.py", line 1788, in _execute
        result = method(*self.path_args, **self.path_kwargs)
      File "/home/s0214/.conda/envs/monster/lib/python3.8/site-packages/tornado/web.py", line 3289, in wrapper
        url = self.get_login_url()
      File "/home/s0214/.conda/envs/monster/lib/python3.8/site-packages/jupyter_server/base/handlers.py", line 783, in get_login_url
        raise web.HTTPError(403)
    tornado.web.HTTPError: HTTP 403: Forbidden
[W 2025-10-05 20:31:13.152 ServerApp] 403 GET /api/sessions?1759678273119 (@172.16.33.3) 1.15ms referer=None
[W 2025-10-05 20:31:13.153 ServerApp] wrote error: 'Forbidden'
    Traceback (most recent call last):
      File "/home/s0214/.conda/envs/monster/lib/python3.8/site-packages/tornado/web.py", line 1788, in _execute
        result = method(*self.path_args, **self.path_kwargs)
      File "/home/s0214/.conda/envs/monster/lib/python3.8/site-packages/tornado/web.py", line 3289, in wrapper
        url = self.get_login_url()
      File "/home/s0214/.conda/envs/monster/lib/python3.8/site-packages/jupyter_server/base/handlers.py", line 783, in get_login_url
        raise web.HTTPError(403)
    tornado.web.HTTPError: HTTP 403: Forbidden
[W 2025-10-05 20:31:13.154 ServerApp] 403 GET /api/kernels?1759678273122 (@172.16.33.3) 1.35ms referer=None
[W 2025-10-05 20:31:13.155 ServerApp] wrote error: 'Forbidden'
    Traceback (most recent call last):
      File "/home/s0214/.conda/envs/monster/lib/python3.8/site-packages/tornado/web.py", line 1788, in _execute
        result = method(*self.path_args, **self.path_kwargs)
      File "/home/s0214/.conda/envs/monster/lib/python3.8/site-packages/tornado/web.py", line 3289, in wrapper
        url = self.get_login_url()
      File "/home/s0214/.conda/envs/monster/lib/python3.8/site-packages/jupyter_server/base/handlers.py", line 783, in get_login_url
        raise web.HTTPError(403)
    tornado.web.HTTPError: HTTP 403: Forbidden
[W 2025-10-05 20:31:13.156 ServerApp] 403 GET /api/kernels?1759678273126 (@172.16.33.3) 1.72ms referer=None
[W 2025-10-05 20:31:13.156 ServerApp] wrote error: 'Forbidden'
    Traceback (most recent call last):
      File "/home/s0214/.conda/envs/monster/lib/python3.8/site-packages/tornado/web.py", line 1788, in _execute
        result = method(*self.path_args, **self.path_kwargs)
      File "/home/s0214/.conda/envs/monster/lib/python3.8/site-packages/tornado/web.py", line 3289, in wrapper
        url = self.get_login_url()
      File "/home/s0214/.conda/envs/monster/lib/python3.8/site-packages/jupyter_server/base/handlers.py", line 783, in get_login_url
        raise web.HTTPError(403)
    tornado.web.HTTPError: HTTP 403: Forbidden
[W 2025-10-05 20:31:13.156 ServerApp] 403 GET /api/kernels?1759678273129 (@172.16.33.3) 2.23ms referer=None
[W 2025-10-05 20:31:13.159 ServerApp] wrote error: 'Forbidden'
    Traceback (most recent call last):
      File "/home/s0214/.conda/envs/monster/lib/python3.8/site-packages/tornado/web.py", line 1788, in _execute
        result = method(*self.path_args, **self.path_kwargs)
      File "/home/s0214/.conda/envs/monster/lib/python3.8/site-packages/tornado/web.py", line 3289, in wrapper
        url = self.get_login_url()
      File "/home/s0214/.conda/envs/monster/lib/python3.8/site-packages/jupyter_server/base/handlers.py", line 783, in get_login_url
        raise web.HTTPError(403)
    tornado.web.HTTPError: HTTP 403: Forbidden
[W 2025-10-05 20:31:13.160 ServerApp] 403 GET /api/kernels?1759678273131 (@172.16.33.3) 3.30ms referer=None
[W 2025-10-05 20:31:13.160 ServerApp] wrote error: 'Forbidden'
    Traceback (most recent call last):
      File "/home/s0214/.conda/envs/monster/lib/python3.8/site-packages/tornado/web.py", line 1788, in _execute
        result = method(*self.path_args, **self.path_kwargs)
      File "/home/s0214/.conda/envs/monster/lib/python3.8/site-packages/tornado/web.py", line 3289, in wrapper
        url = self.get_login_url()
      File "/home/s0214/.conda/envs/monster/lib/python3.8/site-packages/jupyter_server/base/handlers.py", line 783, in get_login_url
        raise web.HTTPError(403)
    tornado.web.HTTPError: HTTP 403: Forbidden
[W 2025-10-05 20:31:13.161 ServerApp] 403 GET /api/sessions?1759678273132 (@172.16.33.3) 3.84ms referer=None
[W 2025-10-05 20:31:13.161 ServerApp] wrote error: 'Forbidden'
    Traceback (most recent call last):
      File "/home/s0214/.conda/envs/monster/lib/python3.8/site-packages/tornado/web.py", line 1788, in _execute
        result = method(*self.path_args, **self.path_kwargs)
      File "/home/s0214/.conda/envs/monster/lib/python3.8/site-packages/tornado/web.py", line 3289, in wrapper
        url = self.get_login_url()
      File "/home/s0214/.conda/envs/monster/lib/python3.8/site-packages/jupyter_server/base/handlers.py", line 783, in get_login_url
        raise web.HTTPError(403)
    tornado.web.HTTPError: HTTP 403: Forbidden
[W 2025-10-05 20:31:13.162 ServerApp] 403 GET /api/kernels?1759678273133 (@172.16.33.3) 4.38ms referer=None
[W 2025-10-05 20:31:13.162 ServerApp] wrote error: 'Forbidden'
    Traceback (most recent call last):
      File "/home/s0214/.conda/envs/monster/lib/python3.8/site-packages/tornado/web.py", line 1788, in _execute
        result = method(*self.path_args, **self.path_kwargs)
      File "/home/s0214/.conda/envs/monster/lib/python3.8/site-packages/tornado/web.py", line 3289, in wrapper
        url = self.get_login_url()
      File "/home/s0214/.conda/envs/monster/lib/python3.8/site-packages/jupyter_server/base/handlers.py", line 783, in get_login_url
        raise web.HTTPError(403)
    tornado.web.HTTPError: HTTP 403: Forbidden
[W 2025-10-05 20:31:13.163 ServerApp] 403 GET /api/sessions?1759678273135 (@172.16.33.3) 4.93ms referer=None
[W 2025-10-05 20:31:13.163 ServerApp] wrote error: 'Forbidden'
    Traceback (most recent call last):
      File "/home/s0214/.conda/envs/monster/lib/python3.8/site-packages/tornado/web.py", line 1788, in _execute
        result = method(*self.path_args, **self.path_kwargs)
      File "/home/s0214/.conda/envs/monster/lib/python3.8/site-packages/tornado/web.py", line 3289, in wrapper
        url = self.get_login_url()
      File "/home/s0214/.conda/envs/monster/lib/python3.8/site-packages/jupyter_server/base/handlers.py", line 783, in get_login_url
        raise web.HTTPError(403)
    tornado.web.HTTPError: HTTP 403: Forbidden
[W 2025-10-05 20:31:13.163 ServerApp] 403 GET /api/kernels?1759678273136 (@172.16.33.3) 5.48ms referer=None
[W 2025-10-05 20:31:13.164 ServerApp] wrote error: 'Forbidden'
    Traceback (most recent call last):
      File "/home/s0214/.conda/envs/monster/lib/python3.8/site-packages/tornado/web.py", line 1788, in _execute
        result = method(*self.path_args, **self.path_kwargs)
      File "/home/s0214/.conda/envs/monster/lib/python3.8/site-packages/tornado/web.py", line 3289, in wrapper
        url = self.get_login_url()
      File "/home/s0214/.conda/envs/monster/lib/python3.8/site-packages/jupyter_server/base/handlers.py", line 783, in get_login_url
        raise web.HTTPError(403)
    tornado.web.HTTPError: HTTP 403: Forbidden
[W 2025-10-05 20:31:13.164 ServerApp] 403 GET /api/sessions?1759678273138 (@172.16.33.3) 6.04ms referer=None
[W 2025-10-05 20:31:13.165 ServerApp] wrote error: 'Forbidden'
    Traceback (most recent call last):
      File "/home/s0214/.conda/envs/monster/lib/python3.8/site-packages/tornado/web.py", line 1788, in _execute
        result = method(*self.path_args, **self.path_kwargs)
      File "/home/s0214/.conda/envs/monster/lib/python3.8/site-packages/tornado/web.py", line 3289, in wrapper
        url = self.get_login_url()
      File "/home/s0214/.conda/envs/monster/lib/python3.8/site-packages/jupyter_server/base/handlers.py", line 783, in get_login_url
        raise web.HTTPError(403)
    tornado.web.HTTPError: HTTP 403: Forbidden
[W 2025-10-05 20:31:13.165 ServerApp] 403 GET /api/kernelspecs?1759678273147 (@172.16.33.3) 6.42ms referer=None
[W 2025-10-05 20:31:13.167 ServerApp] wrote error: 'Forbidden'
    Traceback (most recent call last):
      File "/home/s0214/.conda/envs/monster/lib/python3.8/site-packages/tornado/web.py", line 1788, in _execute
        result = method(*self.path_args, **self.path_kwargs)
      File "/home/s0214/.conda/envs/monster/lib/python3.8/site-packages/tornado/web.py", line 3289, in wrapper
        url = self.get_login_url()
      File "/home/s0214/.conda/envs/monster/lib/python3.8/site-packages/jupyter_server/base/handlers.py", line 783, in get_login_url
        raise web.HTTPError(403)
    tornado.web.HTTPError: HTTP 403: Forbidden
[W 2025-10-05 20:31:13.168 ServerApp] 403 GET /api/kernelspecs?1759678273143 (@172.16.33.3) 2.43ms referer=None
[W 2025-10-05 20:31:13.168 ServerApp] wrote error: 'Forbidden'
    Traceback (most recent call last):
      File "/home/s0214/.conda/envs/monster/lib/python3.8/site-packages/tornado/web.py", line 1788, in _execute
        result = method(*self.path_args, **self.path_kwargs)
      File "/home/s0214/.conda/envs/monster/lib/python3.8/site-packages/tornado/web.py", line 3289, in wrapper
        url = self.get_login_url()
      File "/home/s0214/.conda/envs/monster/lib/python3.8/site-packages/jupyter_server/base/handlers.py", line 783, in get_login_url
        raise web.HTTPError(403)
    tornado.web.HTTPError: HTTP 403: Forbidden
[W 2025-10-05 20:31:13.169 ServerApp] 403 GET /api/kernelspecs?1759678273144 (@172.16.33.3) 2.93ms referer=None
[W 2025-10-05 20:31:13.169 ServerApp] wrote error: 'Forbidden'
    Traceback (most recent call last):
      File "/home/s0214/.conda/envs/monster/lib/python3.8/site-packages/tornado/web.py", line 1788, in _execute
        result = method(*self.path_args, **self.path_kwargs)
      File "/home/s0214/.conda/envs/monster/lib/python3.8/site-packages/tornado/web.py", line 3289, in wrapper
        url = self.get_login_url()
      File "/home/s0214/.conda/envs/monster/lib/python3.8/site-packages/jupyter_server/base/handlers.py", line 783, in get_login_url
        raise web.HTTPError(403)
    tornado.web.HTTPError: HTTP 403: Forbidden
[W 2025-10-05 20:31:13.170 ServerApp] 403 GET /api/kernelspecs?1759678273146 (@172.16.33.3) 3.48ms referer=None
[I 2025-10-05 20:31:13.170 ServerApp] 302 GET / (@172.16.33.3) 3.39ms
[I 2025-10-05 20:31:13.175 ServerApp] 302 GET / (@172.16.33.3) 0.43ms
[I 2025-10-05 20:31:13.176 ServerApp] 302 GET / (@172.16.33.3) 0.53ms
[I 2025-10-05 20:31:13.177 ServerApp] 302 GET / (@172.16.33.3) 0.39ms
[I 2025-10-05 20:31:13.180 JupyterNotebookApp] 302 GET /tree? (@172.16.33.3) 0.57ms
[I 2025-10-05 20:31:13.192 JupyterNotebookApp] 302 GET /tree? (@172.16.33.3) 0.54ms
[I 2025-10-05 20:31:13.195 JupyterNotebookApp] 302 GET /tree? (@172.16.33.3) 0.97ms
[I 2025-10-05 20:31:13.195 JupyterNotebookApp] 302 GET /tree? (@172.16.33.3) 1.11ms
[W 2025-10-05 20:31:13.203 ServerApp] wrote error: 'Forbidden'
    Traceback (most recent call last):
      File "/home/s0214/.conda/envs/monster/lib/python3.8/site-packages/tornado/web.py", line 1788, in _execute
        result = method(*self.path_args, **self.path_kwargs)
      File "/home/s0214/.conda/envs/monster/lib/python3.8/site-packages/tornado/web.py", line 3289, in wrapper
        url = self.get_login_url()
      File "/home/s0214/.conda/envs/monster/lib/python3.8/site-packages/jupyter_server/base/handlers.py", line 783, in get_login_url
        raise web.HTTPError(403)
    tornado.web.HTTPError: HTTP 403: Forbidden
[W 2025-10-05 20:31:13.203 ServerApp] 403 GET /api/kernelspecs?1759678273196 (@172.16.33.3) 0.97ms referer=None
[W 2025-10-05 20:31:13.223 ServerApp] wrote error: 'Forbidden'
    Traceback (most recent call last):
      File "/home/s0214/.conda/envs/monster/lib/python3.8/site-packages/tornado/web.py", line 1788, in _execute
        result = method(*self.path_args, **self.path_kwargs)
      File "/home/s0214/.conda/envs/monster/lib/python3.8/site-packages/tornado/web.py", line 3289, in wrapper
        url = self.get_login_url()
      File "/home/s0214/.conda/envs/monster/lib/python3.8/site-packages/jupyter_server/base/handlers.py", line 783, in get_login_url
        raise web.HTTPError(403)
    tornado.web.HTTPError: HTTP 403: Forbidden
[W 2025-10-05 20:31:13.223 ServerApp] 403 GET /api/kernels?1759678273198 (@172.16.33.3) 2.14ms referer=None
[W 2025-10-05 20:31:13.225 ServerApp] wrote error: 'Forbidden'
    Traceback (most recent call last):
      File "/home/s0214/.conda/envs/monster/lib/python3.8/site-packages/tornado/web.py", line 1788, in _execute
        result = method(*self.path_args, **self.path_kwargs)
      File "/home/s0214/.conda/envs/monster/lib/python3.8/site-packages/tornado/web.py", line 3289, in wrapper
        url = self.get_login_url()
      File "/home/s0214/.conda/envs/monster/lib/python3.8/site-packages/jupyter_server/base/handlers.py", line 783, in get_login_url
        raise web.HTTPError(403)
    tornado.web.HTTPError: HTTP 403: Forbidden
[W 2025-10-05 20:31:13.225 ServerApp] 403 GET /api/kernels?1759678273205 (@172.16.33.3) 3.36ms referer=None
[W 2025-10-05 20:31:13.226 ServerApp] wrote error: 'Forbidden'
    Traceback (most recent call last):
      File "/home/s0214/.conda/envs/monster/lib/python3.8/site-packages/tornado/web.py", line 1788, in _execute
        result = method(*self.path_args, **self.path_kwargs)
      File "/home/s0214/.conda/envs/monster/lib/python3.8/site-packages/tornado/web.py", line 3289, in wrapper
        url = self.get_login_url()
      File "/home/s0214/.conda/envs/monster/lib/python3.8/site-packages/jupyter_server/base/handlers.py", line 783, in get_login_url
        raise web.HTTPError(403)
    tornado.web.HTTPError: HTTP 403: Forbidden
[W 2025-10-05 20:31:13.226 ServerApp] 403 GET /api/kernelspecs?1759678273216 (@172.16.33.3) 3.80ms referer=None
[W 2025-10-05 20:31:13.227 ServerApp] wrote error: 'Forbidden'
    Traceback (most recent call last):
      File "/home/s0214/.conda/envs/monster/lib/python3.8/site-packages/tornado/web.py", line 1788, in _execute
        result = method(*self.path_args, **self.path_kwargs)
      File "/home/s0214/.conda/envs/monster/lib/python3.8/site-packages/tornado/web.py", line 3289, in wrapper
        url = self.get_login_url()
      File "/home/s0214/.conda/envs/monster/lib/python3.8/site-packages/jupyter_server/base/handlers.py", line 783, in get_login_url
        raise web.HTTPError(403)
    tornado.web.HTTPError: HTTP 403: Forbidden
[W 2025-10-05 20:31:13.228 ServerApp] 403 GET /api/sessions?1759678273207 (@172.16.33.3) 1.18ms referer=None
[W 2025-10-05 20:31:13.230 ServerApp] wrote error: 'Forbidden'
    Traceback (most recent call last):
      File "/home/s0214/.conda/envs/monster/lib/python3.8/site-packages/tornado/web.py", line 1788, in _execute
        result = method(*self.path_args, **self.path_kwargs)
      File "/home/s0214/.conda/envs/monster/lib/python3.8/site-packages/tornado/web.py", line 3289, in wrapper
        url = self.get_login_url()
      File "/home/s0214/.conda/envs/monster/lib/python3.8/site-packages/jupyter_server/base/handlers.py", line 783, in get_login_url
        raise web.HTTPError(403)
    tornado.web.HTTPError: HTTP 403: Forbidden
[W 2025-10-05 20:31:13.231 ServerApp] 403 GET /api/kernelspecs?1759678273222 (@172.16.33.3) 0.97ms referer=None
[W 2025-10-05 20:31:13.242 ServerApp] wrote error: 'Forbidden'
    Traceback (most recent call last):
      File "/home/s0214/.conda/envs/monster/lib/python3.8/site-packages/tornado/web.py", line 1788, in _execute
        result = method(*self.path_args, **self.path_kwargs)
      File "/home/s0214/.conda/envs/monster/lib/python3.8/site-packages/tornado/web.py", line 3289, in wrapper
        url = self.get_login_url()
      File "/home/s0214/.conda/envs/monster/lib/python3.8/site-packages/jupyter_server/base/handlers.py", line 783, in get_login_url
        raise web.HTTPError(403)
    tornado.web.HTTPError: HTTP 403: Forbidden
[W 2025-10-05 20:31:13.242 ServerApp] 403 GET /api/kernelspecs?1759678273236 (@172.16.33.3) 0.96ms referer=None
[W 2025-10-05 20:31:13.251 ServerApp] wrote error: 'Forbidden'
    Traceback (most recent call last):
      File "/home/s0214/.conda/envs/monster/lib/python3.8/site-packages/tornado/web.py", line 1788, in _execute
        result = method(*self.path_args, **self.path_kwargs)
      File "/home/s0214/.conda/envs/monster/lib/python3.8/site-packages/tornado/web.py", line 3289, in wrapper
        url = self.get_login_url()
      File "/home/s0214/.conda/envs/monster/lib/python3.8/site-packages/jupyter_server/base/handlers.py", line 783, in get_login_url
        raise web.HTTPError(403)
    tornado.web.HTTPError: HTTP 403: Forbidden
[W 2025-10-05 20:31:13.251 ServerApp] 403 GET /api/kernelspecs?1759678273244 (@172.16.33.3) 0.96ms referer=None
[W 2025-10-05 20:31:13.270 ServerApp] wrote error: 'Forbidden'
    Traceback (most recent call last):
      File "/home/s0214/.conda/envs/monster/lib/python3.8/site-packages/tornado/web.py", line 1788, in _execute
        result = method(*self.path_args, **self.path_kwargs)
      File "/home/s0214/.conda/envs/monster/lib/python3.8/site-packages/tornado/web.py", line 3289, in wrapper
        url = self.get_login_url()
      File "/home/s0214/.conda/envs/monster/lib/python3.8/site-packages/jupyter_server/base/handlers.py", line 783, in get_login_url
        raise web.HTTPError(403)
    tornado.web.HTTPError: HTTP 403: Forbidden
[W 2025-10-05 20:31:13.271 ServerApp] 403 GET /api/kernels?1759678273224 (@172.16.33.3) 0.98ms referer=None
[W 2025-10-05 20:31:13.271 ServerApp] wrote error: 'Forbidden'
    Traceback (most recent call last):
      File "/home/s0214/.conda/envs/monster/lib/python3.8/site-packages/tornado/web.py", line 1788, in _execute
        result = method(*self.path_args, **self.path_kwargs)
      File "/home/s0214/.conda/envs/monster/lib/python3.8/site-packages/tornado/web.py", line 3289, in wrapper
        url = self.get_login_url()
      File "/home/s0214/.conda/envs/monster/lib/python3.8/site-packages/jupyter_server/base/handlers.py", line 783, in get_login_url
        raise web.HTTPError(403)
    tornado.web.HTTPError: HTTP 403: Forbidden
[W 2025-10-05 20:31:13.272 ServerApp] 403 GET /api/kernels?1759678273228 (@172.16.33.3) 0.98ms referer=None
[W 2025-10-05 20:31:13.276 ServerApp] wrote error: 'Forbidden'
    Traceback (most recent call last):
      File "/home/s0214/.conda/envs/monster/lib/python3.8/site-packages/tornado/web.py", line 1788, in _execute
        result = method(*self.path_args, **self.path_kwargs)
      File "/home/s0214/.conda/envs/monster/lib/python3.8/site-packages/tornado/web.py", line 3289, in wrapper
        url = self.get_login_url()
      File "/home/s0214/.conda/envs/monster/lib/python3.8/site-packages/jupyter_server/base/handlers.py", line 783, in get_login_url
        raise web.HTTPError(403)
    tornado.web.HTTPError: HTTP 403: Forbidden
[W 2025-10-05 20:31:13.277 ServerApp] 403 GET /api/sessions?1759678273231 (@172.16.33.3) 1.12ms referer=None
[W 2025-10-05 20:31:13.278 ServerApp] wrote error: 'Forbidden'
    Traceback (most recent call last):
      File "/home/s0214/.conda/envs/monster/lib/python3.8/site-packages/tornado/web.py", line 1788, in _execute
        result = method(*self.path_args, **self.path_kwargs)
      File "/home/s0214/.conda/envs/monster/lib/python3.8/site-packages/tornado/web.py", line 3289, in wrapper
        url = self.get_login_url()
      File "/home/s0214/.conda/envs/monster/lib/python3.8/site-packages/jupyter_server/base/handlers.py", line 783, in get_login_url
        raise web.HTTPError(403)
    tornado.web.HTTPError: HTTP 403: Forbidden
[W 2025-10-05 20:31:13.278 ServerApp] 403 GET /api/kernels?1759678273238 (@172.16.33.3) 1.19ms referer=None
[W 2025-10-05 20:31:13.280 ServerApp] wrote error: 'Forbidden'
    Traceback (most recent call last):
      File "/home/s0214/.conda/envs/monster/lib/python3.8/site-packages/tornado/web.py", line 1788, in _execute
        result = method(*self.path_args, **self.path_kwargs)
      File "/home/s0214/.conda/envs/monster/lib/python3.8/site-packages/tornado/web.py", line 3289, in wrapper
        url = self.get_login_url()
      File "/home/s0214/.conda/envs/monster/lib/python3.8/site-packages/jupyter_server/base/handlers.py", line 783, in get_login_url
        raise web.HTTPError(403)
    tornado.web.HTTPError: HTTP 403: Forbidden
[W 2025-10-05 20:31:13.280 ServerApp] 403 GET /api/kernels?1759678273247 (@172.16.33.3) 1.54ms referer=None
[W 2025-10-05 20:31:13.280 ServerApp] wrote error: 'Forbidden'
    Traceback (most recent call last):
      File "/home/s0214/.conda/envs/monster/lib/python3.8/site-packages/tornado/web.py", line 1788, in _execute
        result = method(*self.path_args, **self.path_kwargs)
      File "/home/s0214/.conda/envs/monster/lib/python3.8/site-packages/tornado/web.py", line 3289, in wrapper
        url = self.get_login_url()
      File "/home/s0214/.conda/envs/monster/lib/python3.8/site-packages/jupyter_server/base/handlers.py", line 783, in get_login_url
        raise web.HTTPError(403)
    tornado.web.HTTPError: HTTP 403: Forbidden
[W 2025-10-05 20:31:13.281 ServerApp] 403 GET /api/kernelspecs?1759678273250 (@172.16.33.3) 2.07ms referer=None
[W 2025-10-05 20:31:13.282 ServerApp] wrote error: 'Forbidden'
    Traceback (most recent call last):
      File "/home/s0214/.conda/envs/monster/lib/python3.8/site-packages/tornado/web.py", line 1788, in _execute
        result = method(*self.path_args, **self.path_kwargs)
      File "/home/s0214/.conda/envs/monster/lib/python3.8/site-packages/tornado/web.py", line 3289, in wrapper
        url = self.get_login_url()
      File "/home/s0214/.conda/envs/monster/lib/python3.8/site-packages/jupyter_server/base/handlers.py", line 783, in get_login_url
        raise web.HTTPError(403)
    tornado.web.HTTPError: HTTP 403: Forbidden
[W 2025-10-05 20:31:13.283 ServerApp] 403 GET /api/kernels?1759678273252 (@172.16.33.3) 1.71ms referer=None
[W 2025-10-05 20:31:13.283 ServerApp] wrote error: 'Forbidden'
    Traceback (most recent call last):
      File "/home/s0214/.conda/envs/monster/lib/python3.8/site-packages/tornado/web.py", line 1788, in _execute
        result = method(*self.path_args, **self.path_kwargs)
      File "/home/s0214/.conda/envs/monster/lib/python3.8/site-packages/tornado/web.py", line 3289, in wrapper
        url = self.get_login_url()
      File "/home/s0214/.conda/envs/monster/lib/python3.8/site-packages/jupyter_server/base/handlers.py", line 783, in get_login_url
        raise web.HTTPError(403)
    tornado.web.HTTPError: HTTP 403: Forbidden
[W 2025-10-05 20:31:13.284 ServerApp] 403 GET /api/sessions?1759678273254 (@172.16.33.3) 2.23ms referer=None
[W 2025-10-05 20:31:13.284 ServerApp] wrote error: 'Forbidden'
    Traceback (most recent call last):
      File "/home/s0214/.conda/envs/monster/lib/python3.8/site-packages/tornado/web.py", line 1788, in _execute
        result = method(*self.path_args, **self.path_kwargs)
      File "/home/s0214/.conda/envs/monster/lib/python3.8/site-packages/tornado/web.py", line 3289, in wrapper
        url = self.get_login_url()
      File "/home/s0214/.conda/envs/monster/lib/python3.8/site-packages/jupyter_server/base/handlers.py", line 783, in get_login_url
        raise web.HTTPError(403)
    tornado.web.HTTPError: HTTP 403: Forbidden
[W 2025-10-05 20:31:13.285 ServerApp] 403 GET /api/kernels?1759678273256 (@172.16.33.3) 2.77ms referer=None
[W 2025-10-05 20:31:13.286 ServerApp] wrote error: 'Forbidden'
    Traceback (most recent call last):
      File "/home/s0214/.conda/envs/monster/lib/python3.8/site-packages/tornado/web.py", line 1788, in _execute
        result = method(*self.path_args, **self.path_kwargs)
      File "/home/s0214/.conda/envs/monster/lib/python3.8/site-packages/tornado/web.py", line 3289, in wrapper
        url = self.get_login_url()
      File "/home/s0214/.conda/envs/monster/lib/python3.8/site-packages/jupyter_server/base/handlers.py", line 783, in get_login_url
        raise web.HTTPError(403)
    tornado.web.HTTPError: HTTP 403: Forbidden
[W 2025-10-05 20:31:13.287 ServerApp] 403 GET /api/sessions?1759678273258 (@172.16.33.3) 1.75ms referer=None
[W 2025-10-05 20:31:13.287 ServerApp] wrote error: 'Forbidden'
    Traceback (most recent call last):
      File "/home/s0214/.conda/envs/monster/lib/python3.8/site-packages/tornado/web.py", line 1788, in _execute
        result = method(*self.path_args, **self.path_kwargs)
      File "/home/s0214/.conda/envs/monster/lib/python3.8/site-packages/tornado/web.py", line 3289, in wrapper
        url = self.get_login_url()
      File "/home/s0214/.conda/envs/monster/lib/python3.8/site-packages/jupyter_server/base/handlers.py", line 783, in get_login_url
        raise web.HTTPError(403)
    tornado.web.HTTPError: HTTP 403: Forbidden
[W 2025-10-05 20:31:13.287 ServerApp] 403 GET /api/kernelspecs?1759678273270 (@172.16.33.3) 2.26ms referer=None
[W 2025-10-05 20:31:13.288 ServerApp] wrote error: 'Forbidden'
    Traceback (most recent call last):
      File "/home/s0214/.conda/envs/monster/lib/python3.8/site-packages/tornado/web.py", line 1788, in _execute
        result = method(*self.path_args, **self.path_kwargs)
      File "/home/s0214/.conda/envs/monster/lib/python3.8/site-packages/tornado/web.py", line 3289, in wrapper
        url = self.get_login_url()
      File "/home/s0214/.conda/envs/monster/lib/python3.8/site-packages/jupyter_server/base/handlers.py", line 783, in get_login_url
        raise web.HTTPError(403)
    tornado.web.HTTPError: HTTP 403: Forbidden
[W 2025-10-05 20:31:13.288 ServerApp] 403 GET /api/kernelspecs?1759678273271 (@172.16.33.3) 2.79ms referer=None
[W 2025-10-05 20:31:16.081 ServerApp] 404 GET /nbextensions/jupyter-js-widgets/extension.js (@172.16.33.3) 7.74ms referer=None
[I 2025-10-05 20:31:16.081 ServerApp] 302 GET / (@172.16.33.3) 7.62ms
[I 2025-10-05 20:31:16.085 JupyterNotebookApp] 302 GET /tree? (@172.16.33.3) 0.48ms
[W 2025-10-05 20:31:16.094 ServerApp] 404 GET /nbextensions/jupyter-js-widgets/extension.js (@172.16.33.3) 0.87ms referer=None
slurmstepd: error: *** JOB 19593537 ON tesla-v100 CANCELLED AT 2025-10-05T21:29:41 DUE TO TIME LIMIT ***
