Both `sys_prefix` and `user` level settings are read-only, cannot auto-migrate `disabledExtensions` to `lockedExtensions`
[I 2025-09-26 17:21:06.735 ServerApp] jupyter_lsp | extension was successfully linked.
[I 2025-09-26 17:21:06.740 ServerApp] jupyter_server_terminals | extension was successfully linked.
[I 2025-09-26 17:21:06.746 ServerApp] jupyterlab | extension was successfully linked.
[I 2025-09-26 17:21:06.751 ServerApp] notebook | extension was successfully linked.
[I 2025-09-26 17:21:07.188 ServerApp] notebook_shim | extension was successfully linked.
[I 2025-09-26 17:21:07.247 ServerApp] notebook_shim | extension was successfully loaded.
[I 2025-09-26 17:21:07.250 ServerApp] jupyter_lsp | extension was successfully loaded.
[I 2025-09-26 17:21:07.252 ServerApp] jupyter_server_terminals | extension was successfully loaded.
[I 2025-09-26 17:21:07.260 LabApp] JupyterLab extension loaded from /home/s0214/.conda/envs/monster/lib/python3.8/site-packages/jupyterlab
[I 2025-09-26 17:21:07.260 LabApp] JupyterLab application directory is /misc/home4/s0214/.conda/envs/monster/share/jupyter/lab
[I 2025-09-26 17:21:07.262 LabApp] Extension Manager is 'pypi'.
[I 2025-09-26 17:21:07.345 ServerApp] jupyterlab | extension was successfully loaded.
[I 2025-09-26 17:21:07.353 ServerApp] notebook | extension was successfully loaded.
[I 2025-09-26 17:21:07.354 ServerApp] Serving notebooks from local directory: /misc/home6/s0214/MonSter
[I 2025-09-26 17:21:07.354 ServerApp] Jupyter Server 2.14.2 is running at:
[I 2025-09-26 17:21:07.354 ServerApp] http://tesla-v100:8888/tree?token=c85f2a2cadaace926e126c075fcbc06187baebe0cc7183ec
[I 2025-09-26 17:21:07.354 ServerApp]     http://127.0.0.1:8888/tree?token=c85f2a2cadaace926e126c075fcbc06187baebe0cc7183ec
[I 2025-09-26 17:21:07.354 ServerApp] Use Control-C to stop this server and shut down all kernels (twice to skip confirmation).
[C 2025-09-26 17:21:07.372 ServerApp] 
    
    To access the server, open this file in a browser:
        file:///misc/home4/s0214/.local/share/jupyter/runtime/jpserver-2058958-open.html
    Or copy and paste one of these URLs:
        http://tesla-v100:8888/tree?token=c85f2a2cadaace926e126c075fcbc06187baebe0cc7183ec
        http://127.0.0.1:8888/tree?token=c85f2a2cadaace926e126c075fcbc06187baebe0cc7183ec
[I 2025-09-26 17:21:07.481 ServerApp] Skipped non-installed server(s): basedpyright, bash-language-server, dockerfile-language-server-nodejs, javascript-typescript-langserver, jedi-language-server, julia-language-server, pyrefly, pyright, python-language-server, python-lsp-server, r-languageserver, sql-language-server, texlab, typescript-language-server, unified-language-server, vscode-css-languageserver-bin, vscode-html-languageserver-bin, vscode-json-languageserver-bin, yaml-language-server
[I 2025-09-26 17:22:08.990 ServerApp] 302 GET / (@172.16.33.3) 0.50ms
[I 2025-09-26 17:22:08.995 JupyterNotebookApp] 302 GET /tree? (@172.16.33.3) 0.63ms
[I 2025-09-26 17:22:10.923 ServerApp] 302 GET / (@172.16.33.3) 0.36ms
[I 2025-09-26 17:22:10.926 JupyterNotebookApp] 302 GET /tree? (@172.16.33.3) 0.46ms
[I 2025-09-26 17:22:44.025 ServerApp] 302 GET / (@172.16.33.3) 0.41ms
[I 2025-09-26 17:22:44.029 JupyterNotebookApp] 302 GET /tree? (@172.16.33.3) 0.46ms
[I 2025-09-26 17:22:44.116 ServerApp] Kernel started: b1c5c31d-4983-4779-a794-fad4ab3661d9
[IPKernelApp] ERROR | Failed to create history session in /misc/home4/s0214/.ipython/profile_default/history.sqlite. History will not be saved.
Traceback (most recent call last):
  File "/home/s0214/.conda/envs/monster/lib/python3.8/site-packages/IPython/core/history.py", line 543, in __init__
    self.new_session()
  File "<decorator-gen-15>", line 2, in new_session
  File "/home/s0214/.conda/envs/monster/lib/python3.8/site-packages/IPython/core/history.py", line 58, in needs_sqlite
    return f(self, *a, **kw)
  File "/home/s0214/.conda/envs/monster/lib/python3.8/site-packages/IPython/core/history.py", line 568, in new_session
    cur = conn.execute("""INSERT INTO sessions VALUES (NULL, ?, NULL,
sqlite3.OperationalError: unable to open database file
[I 2025-09-26 17:22:45.324 ServerApp] Connecting to kernel b1c5c31d-4983-4779-a794-fad4ab3661d9.
[I 2025-09-26 17:22:45.595 ServerApp] 302 GET / (@172.16.33.3) 4.49ms
[I 2025-09-26 17:22:45.596 ServerApp] 302 GET / (@172.16.33.3) 4.50ms
[I 2025-09-26 17:22:45.597 ServerApp] 302 GET / (@172.16.33.3) 0.47ms
[I 2025-09-26 17:22:45.618 JupyterNotebookApp] 302 GET /tree? (@172.16.33.3) 1.48ms
[I 2025-09-26 17:22:45.619 JupyterNotebookApp] 302 GET /tree? (@172.16.33.3) 1.64ms
[I 2025-09-26 17:22:45.619 JupyterNotebookApp] 302 GET /tree? (@172.16.33.3) 1.79ms
[W 2025-09-26 17:22:45.643 ServerApp] wrote error: 'Forbidden'
    Traceback (most recent call last):
      File "/home/s0214/.conda/envs/monster/lib/python3.8/site-packages/tornado/web.py", line 1788, in _execute
        result = method(*self.path_args, **self.path_kwargs)
      File "/home/s0214/.conda/envs/monster/lib/python3.8/site-packages/tornado/web.py", line 3289, in wrapper
        url = self.get_login_url()
      File "/home/s0214/.conda/envs/monster/lib/python3.8/site-packages/jupyter_server/base/handlers.py", line 783, in get_login_url
        raise web.HTTPError(403)
    tornado.web.HTTPError: HTTP 403: Forbidden
[W 2025-09-26 17:22:45.646 ServerApp] 403 GET /api/kernelspecs?1758889365639 (@172.16.33.3) 3.39ms referer=None
[W 2025-09-26 17:22:45.648 ServerApp] wrote error: 'Forbidden'
    Traceback (most recent call last):
      File "/home/s0214/.conda/envs/monster/lib/python3.8/site-packages/tornado/web.py", line 1788, in _execute
        result = method(*self.path_args, **self.path_kwargs)
      File "/home/s0214/.conda/envs/monster/lib/python3.8/site-packages/tornado/web.py", line 3289, in wrapper
        url = self.get_login_url()
      File "/home/s0214/.conda/envs/monster/lib/python3.8/site-packages/jupyter_server/base/handlers.py", line 783, in get_login_url
        raise web.HTTPError(403)
    tornado.web.HTTPError: HTTP 403: Forbidden
[W 2025-09-26 17:22:45.648 ServerApp] 403 GET /api/kernelspecs?1758889365644 (@172.16.33.3) 1.01ms referer=None
[W 2025-09-26 17:22:45.650 ServerApp] wrote error: 'Forbidden'
    Traceback (most recent call last):
      File "/home/s0214/.conda/envs/monster/lib/python3.8/site-packages/tornado/web.py", line 1788, in _execute
        result = method(*self.path_args, **self.path_kwargs)
      File "/home/s0214/.conda/envs/monster/lib/python3.8/site-packages/tornado/web.py", line 3289, in wrapper
        url = self.get_login_url()
      File "/home/s0214/.conda/envs/monster/lib/python3.8/site-packages/jupyter_server/base/handlers.py", line 783, in get_login_url
        raise web.HTTPError(403)
    tornado.web.HTTPError: HTTP 403: Forbidden
[W 2025-09-26 17:22:45.651 ServerApp] 403 GET /api/kernelspecs?1758889365648 (@172.16.33.3) 0.98ms referer=None
[W 2025-09-26 17:22:45.661 ServerApp] wrote error: 'Forbidden'
    Traceback (most recent call last):
      File "/home/s0214/.conda/envs/monster/lib/python3.8/site-packages/tornado/web.py", line 1788, in _execute
        result = method(*self.path_args, **self.path_kwargs)
      File "/home/s0214/.conda/envs/monster/lib/python3.8/site-packages/tornado/web.py", line 3289, in wrapper
        url = self.get_login_url()
      File "/home/s0214/.conda/envs/monster/lib/python3.8/site-packages/jupyter_server/base/handlers.py", line 783, in get_login_url
        raise web.HTTPError(403)
    tornado.web.HTTPError: HTTP 403: Forbidden
[W 2025-09-26 17:22:45.661 ServerApp] 403 GET /api/kernels?1758889365640 (@172.16.33.3) 1.02ms referer=None
[W 2025-09-26 17:22:45.666 ServerApp] wrote error: 'Forbidden'
    Traceback (most recent call last):
      File "/home/s0214/.conda/envs/monster/lib/python3.8/site-packages/tornado/web.py", line 1788, in _execute
        result = method(*self.path_args, **self.path_kwargs)
      File "/home/s0214/.conda/envs/monster/lib/python3.8/site-packages/tornado/web.py", line 3289, in wrapper
        url = self.get_login_url()
      File "/home/s0214/.conda/envs/monster/lib/python3.8/site-packages/jupyter_server/base/handlers.py", line 783, in get_login_url
        raise web.HTTPError(403)
    tornado.web.HTTPError: HTTP 403: Forbidden
[W 2025-09-26 17:22:45.667 ServerApp] 403 GET /api/kernels?1758889365645 (@172.16.33.3) 1.16ms referer=None
[W 2025-09-26 17:22:45.668 ServerApp] wrote error: 'Forbidden'
    Traceback (most recent call last):
      File "/home/s0214/.conda/envs/monster/lib/python3.8/site-packages/tornado/web.py", line 1788, in _execute
        result = method(*self.path_args, **self.path_kwargs)
      File "/home/s0214/.conda/envs/monster/lib/python3.8/site-packages/tornado/web.py", line 3289, in wrapper
        url = self.get_login_url()
      File "/home/s0214/.conda/envs/monster/lib/python3.8/site-packages/jupyter_server/base/handlers.py", line 783, in get_login_url
        raise web.HTTPError(403)
    tornado.web.HTTPError: HTTP 403: Forbidden
[W 2025-09-26 17:22:45.668 ServerApp] 403 GET /api/kernels?1758889365648 (@172.16.33.3) 1.34ms referer=None
[W 2025-09-26 17:22:45.670 ServerApp] wrote error: 'Forbidden'
    Traceback (most recent call last):
      File "/home/s0214/.conda/envs/monster/lib/python3.8/site-packages/tornado/web.py", line 1788, in _execute
        result = method(*self.path_args, **self.path_kwargs)
      File "/home/s0214/.conda/envs/monster/lib/python3.8/site-packages/tornado/web.py", line 3289, in wrapper
        url = self.get_login_url()
      File "/home/s0214/.conda/envs/monster/lib/python3.8/site-packages/jupyter_server/base/handlers.py", line 783, in get_login_url
        raise web.HTTPError(403)
    tornado.web.HTTPError: HTTP 403: Forbidden
[W 2025-09-26 17:22:45.670 ServerApp] 403 GET /api/kernels?1758889365650 (@172.16.33.3) 2.06ms referer=None
[W 2025-09-26 17:22:45.671 ServerApp] wrote error: 'Forbidden'
    Traceback (most recent call last):
      File "/home/s0214/.conda/envs/monster/lib/python3.8/site-packages/tornado/web.py", line 1788, in _execute
        result = method(*self.path_args, **self.path_kwargs)
      File "/home/s0214/.conda/envs/monster/lib/python3.8/site-packages/tornado/web.py", line 3289, in wrapper
        url = self.get_login_url()
      File "/home/s0214/.conda/envs/monster/lib/python3.8/site-packages/jupyter_server/base/handlers.py", line 783, in get_login_url
        raise web.HTTPError(403)
    tornado.web.HTTPError: HTTP 403: Forbidden
[W 2025-09-26 17:22:45.671 ServerApp] 403 GET /api/sessions?1758889365651 (@172.16.33.3) 2.58ms referer=None
[W 2025-09-26 17:22:45.673 ServerApp] wrote error: 'Forbidden'
    Traceback (most recent call last):
      File "/home/s0214/.conda/envs/monster/lib/python3.8/site-packages/tornado/web.py", line 1788, in _execute
        result = method(*self.path_args, **self.path_kwargs)
      File "/home/s0214/.conda/envs/monster/lib/python3.8/site-packages/tornado/web.py", line 3289, in wrapper
        url = self.get_login_url()
      File "/home/s0214/.conda/envs/monster/lib/python3.8/site-packages/jupyter_server/base/handlers.py", line 783, in get_login_url
        raise web.HTTPError(403)
    tornado.web.HTTPError: HTTP 403: Forbidden
[W 2025-09-26 17:22:45.673 ServerApp] 403 GET /api/kernelspecs?1758889365662 (@172.16.33.3) 4.07ms referer=None
[W 2025-09-26 17:22:45.674 ServerApp] wrote error: 'Forbidden'
    Traceback (most recent call last):
      File "/home/s0214/.conda/envs/monster/lib/python3.8/site-packages/tornado/web.py", line 1788, in _execute
        result = method(*self.path_args, **self.path_kwargs)
      File "/home/s0214/.conda/envs/monster/lib/python3.8/site-packages/tornado/web.py", line 3289, in wrapper
        url = self.get_login_url()
      File "/home/s0214/.conda/envs/monster/lib/python3.8/site-packages/jupyter_server/base/handlers.py", line 783, in get_login_url
        raise web.HTTPError(403)
    tornado.web.HTTPError: HTTP 403: Forbidden
[W 2025-09-26 17:22:45.674 ServerApp] 403 GET /api/kernels?1758889365652 (@172.16.33.3) 2.63ms referer=None
[W 2025-09-26 17:22:45.675 ServerApp] wrote error: 'Forbidden'
    Traceback (most recent call last):
      File "/home/s0214/.conda/envs/monster/lib/python3.8/site-packages/tornado/web.py", line 1788, in _execute
        result = method(*self.path_args, **self.path_kwargs)
      File "/home/s0214/.conda/envs/monster/lib/python3.8/site-packages/tornado/web.py", line 3289, in wrapper
        url = self.get_login_url()
      File "/home/s0214/.conda/envs/monster/lib/python3.8/site-packages/jupyter_server/base/handlers.py", line 783, in get_login_url
        raise web.HTTPError(403)
    tornado.web.HTTPError: HTTP 403: Forbidden
[W 2025-09-26 17:22:45.675 ServerApp] 403 GET /api/sessions?1758889365653 (@172.16.33.3) 3.15ms referer=None
[W 2025-09-26 17:22:45.675 ServerApp] wrote error: 'Forbidden'
    Traceback (most recent call last):
      File "/home/s0214/.conda/envs/monster/lib/python3.8/site-packages/tornado/web.py", line 1788, in _execute
        result = method(*self.path_args, **self.path_kwargs)
      File "/home/s0214/.conda/envs/monster/lib/python3.8/site-packages/tornado/web.py", line 3289, in wrapper
        url = self.get_login_url()
      File "/home/s0214/.conda/envs/monster/lib/python3.8/site-packages/jupyter_server/base/handlers.py", line 783, in get_login_url
        raise web.HTTPError(403)
    tornado.web.HTTPError: HTTP 403: Forbidden
[W 2025-09-26 17:22:45.676 ServerApp] 403 GET /api/kernels?1758889365654 (@172.16.33.3) 3.68ms referer=None
[W 2025-09-26 17:22:45.678 ServerApp] wrote error: 'Forbidden'
    Traceback (most recent call last):
      File "/home/s0214/.conda/envs/monster/lib/python3.8/site-packages/tornado/web.py", line 1788, in _execute
        result = method(*self.path_args, **self.path_kwargs)
      File "/home/s0214/.conda/envs/monster/lib/python3.8/site-packages/tornado/web.py", line 3289, in wrapper
        url = self.get_login_url()
      File "/home/s0214/.conda/envs/monster/lib/python3.8/site-packages/jupyter_server/base/handlers.py", line 783, in get_login_url
        raise web.HTTPError(403)
    tornado.web.HTTPError: HTTP 403: Forbidden
[W 2025-09-26 17:22:45.678 ServerApp] 403 GET /api/sessions?1758889365657 (@172.16.33.3) 1.84ms referer=None
[W 2025-09-26 17:22:45.678 ServerApp] wrote error: 'Forbidden'
    Traceback (most recent call last):
      File "/home/s0214/.conda/envs/monster/lib/python3.8/site-packages/tornado/web.py", line 1788, in _execute
        result = method(*self.path_args, **self.path_kwargs)
      File "/home/s0214/.conda/envs/monster/lib/python3.8/site-packages/tornado/web.py", line 3289, in wrapper
        url = self.get_login_url()
      File "/home/s0214/.conda/envs/monster/lib/python3.8/site-packages/jupyter_server/base/handlers.py", line 783, in get_login_url
        raise web.HTTPError(403)
    tornado.web.HTTPError: HTTP 403: Forbidden
[W 2025-09-26 17:22:45.679 ServerApp] 403 GET /api/kernelspecs?1758889365660 (@172.16.33.3) 2.32ms referer=None
[W 2025-09-26 17:22:45.679 ServerApp] wrote error: 'Forbidden'
    Traceback (most recent call last):
      File "/home/s0214/.conda/envs/monster/lib/python3.8/site-packages/tornado/web.py", line 1788, in _execute
        result = method(*self.path_args, **self.path_kwargs)
      File "/home/s0214/.conda/envs/monster/lib/python3.8/site-packages/tornado/web.py", line 3289, in wrapper
        url = self.get_login_url()
      File "/home/s0214/.conda/envs/monster/lib/python3.8/site-packages/jupyter_server/base/handlers.py", line 783, in get_login_url
        raise web.HTTPError(403)
    tornado.web.HTTPError: HTTP 403: Forbidden
[W 2025-09-26 17:22:45.680 ServerApp] 403 GET /api/kernelspecs?1758889365661 (@172.16.33.3) 2.86ms referer=None
[I 2025-09-26 17:22:45.682 ServerApp] 302 GET / (@172.16.33.3) 1.04ms
[I 2025-09-26 17:22:45.682 ServerApp] 302 GET / (@172.16.33.3) 0.90ms
[I 2025-09-26 17:22:45.683 ServerApp] 302 GET / (@172.16.33.3) 0.44ms
[I 2025-09-26 17:22:45.687 JupyterNotebookApp] 302 GET /tree? (@172.16.33.3) 1.35ms
[I 2025-09-26 17:22:45.688 JupyterNotebookApp] 302 GET /tree? (@172.16.33.3) 1.40ms
[I 2025-09-26 17:22:45.688 JupyterNotebookApp] 302 GET /tree? (@172.16.33.3) 1.39ms
[W 2025-09-26 17:22:45.699 ServerApp] wrote error: 'Forbidden'
    Traceback (most recent call last):
      File "/home/s0214/.conda/envs/monster/lib/python3.8/site-packages/tornado/web.py", line 1788, in _execute
        result = method(*self.path_args, **self.path_kwargs)
      File "/home/s0214/.conda/envs/monster/lib/python3.8/site-packages/tornado/web.py", line 3289, in wrapper
        url = self.get_login_url()
      File "/home/s0214/.conda/envs/monster/lib/python3.8/site-packages/jupyter_server/base/handlers.py", line 783, in get_login_url
        raise web.HTTPError(403)
    tornado.web.HTTPError: HTTP 403: Forbidden
[W 2025-09-26 17:22:45.699 ServerApp] 403 GET /api/kernelspecs?1758889365696 (@172.16.33.3) 0.98ms referer=None
[W 2025-09-26 17:22:45.702 ServerApp] wrote error: 'Forbidden'
    Traceback (most recent call last):
      File "/home/s0214/.conda/envs/monster/lib/python3.8/site-packages/tornado/web.py", line 1788, in _execute
        result = method(*self.path_args, **self.path_kwargs)
      File "/home/s0214/.conda/envs/monster/lib/python3.8/site-packages/tornado/web.py", line 3289, in wrapper
        url = self.get_login_url()
      File "/home/s0214/.conda/envs/monster/lib/python3.8/site-packages/jupyter_server/base/handlers.py", line 783, in get_login_url
        raise web.HTTPError(403)
    tornado.web.HTTPError: HTTP 403: Forbidden
[W 2025-09-26 17:22:45.702 ServerApp] 403 GET /api/kernelspecs?1758889365699 (@172.16.33.3) 0.96ms referer=None
[W 2025-09-26 17:22:45.705 ServerApp] wrote error: 'Forbidden'
    Traceback (most recent call last):
      File "/home/s0214/.conda/envs/monster/lib/python3.8/site-packages/tornado/web.py", line 1788, in _execute
        result = method(*self.path_args, **self.path_kwargs)
      File "/home/s0214/.conda/envs/monster/lib/python3.8/site-packages/tornado/web.py", line 3289, in wrapper
        url = self.get_login_url()
      File "/home/s0214/.conda/envs/monster/lib/python3.8/site-packages/jupyter_server/base/handlers.py", line 783, in get_login_url
        raise web.HTTPError(403)
    tornado.web.HTTPError: HTTP 403: Forbidden
[W 2025-09-26 17:22:45.705 ServerApp] 403 GET /api/kernelspecs?1758889365702 (@172.16.33.3) 0.97ms referer=None
[W 2025-09-26 17:22:45.715 ServerApp] wrote error: 'Forbidden'
    Traceback (most recent call last):
      File "/home/s0214/.conda/envs/monster/lib/python3.8/site-packages/tornado/web.py", line 1788, in _execute
        result = method(*self.path_args, **self.path_kwargs)
      File "/home/s0214/.conda/envs/monster/lib/python3.8/site-packages/tornado/web.py", line 3289, in wrapper
        url = self.get_login_url()
      File "/home/s0214/.conda/envs/monster/lib/python3.8/site-packages/jupyter_server/base/handlers.py", line 783, in get_login_url
        raise web.HTTPError(403)
    tornado.web.HTTPError: HTTP 403: Forbidden
[W 2025-09-26 17:22:45.716 ServerApp] 403 GET /api/kernels?1758889365697 (@172.16.33.3) 1.58ms referer=None
[W 2025-09-26 17:22:45.716 ServerApp] wrote error: 'Forbidden'
    Traceback (most recent call last):
      File "/home/s0214/.conda/envs/monster/lib/python3.8/site-packages/tornado/web.py", line 1788, in _execute
        result = method(*self.path_args, **self.path_kwargs)
      File "/home/s0214/.conda/envs/monster/lib/python3.8/site-packages/tornado/web.py", line 3289, in wrapper
        url = self.get_login_url()
      File "/home/s0214/.conda/envs/monster/lib/python3.8/site-packages/jupyter_server/base/handlers.py", line 783, in get_login_url
        raise web.HTTPError(403)
    tornado.web.HTTPError: HTTP 403: Forbidden
[W 2025-09-26 17:22:45.717 ServerApp] 403 GET /api/kernels?1758889365700 (@172.16.33.3) 2.08ms referer=None
[W 2025-09-26 17:22:45.717 ServerApp] wrote error: 'Forbidden'
    Traceback (most recent call last):
      File "/home/s0214/.conda/envs/monster/lib/python3.8/site-packages/tornado/web.py", line 1788, in _execute
        result = method(*self.path_args, **self.path_kwargs)
      File "/home/s0214/.conda/envs/monster/lib/python3.8/site-packages/tornado/web.py", line 3289, in wrapper
        url = self.get_login_url()
      File "/home/s0214/.conda/envs/monster/lib/python3.8/site-packages/jupyter_server/base/handlers.py", line 783, in get_login_url
        raise web.HTTPError(403)
    tornado.web.HTTPError: HTTP 403: Forbidden
[W 2025-09-26 17:22:45.718 ServerApp] 403 GET /api/kernels?1758889365703 (@172.16.33.3) 2.64ms referer=None
[W 2025-09-26 17:22:45.720 ServerApp] wrote error: 'Forbidden'
    Traceback (most recent call last):
      File "/home/s0214/.conda/envs/monster/lib/python3.8/site-packages/tornado/web.py", line 1788, in _execute
        result = method(*self.path_args, **self.path_kwargs)
      File "/home/s0214/.conda/envs/monster/lib/python3.8/site-packages/tornado/web.py", line 3289, in wrapper
        url = self.get_login_url()
      File "/home/s0214/.conda/envs/monster/lib/python3.8/site-packages/jupyter_server/base/handlers.py", line 783, in get_login_url
        raise web.HTTPError(403)
    tornado.web.HTTPError: HTTP 403: Forbidden
[W 2025-09-26 17:22:45.721 ServerApp] 403 GET /api/kernels?1758889365704 (@172.16.33.3) 1.06ms referer=None
[W 2025-09-26 17:22:45.721 ServerApp] wrote error: 'Forbidden'
    Traceback (most recent call last):
      File "/home/s0214/.conda/envs/monster/lib/python3.8/site-packages/tornado/web.py", line 1788, in _execute
        result = method(*self.path_args, **self.path_kwargs)
      File "/home/s0214/.conda/envs/monster/lib/python3.8/site-packages/tornado/web.py", line 3289, in wrapper
        url = self.get_login_url()
      File "/home/s0214/.conda/envs/monster/lib/python3.8/site-packages/jupyter_server/base/handlers.py", line 783, in get_login_url
        raise web.HTTPError(403)
    tornado.web.HTTPError: HTTP 403: Forbidden
[W 2025-09-26 17:22:45.722 ServerApp] 403 GET /api/sessions?1758889365705 (@172.16.33.3) 1.19ms referer=None
[W 2025-09-26 17:22:45.723 ServerApp] wrote error: 'Forbidden'
    Traceback (most recent call last):
      File "/home/s0214/.conda/envs/monster/lib/python3.8/site-packages/tornado/web.py", line 1788, in _execute
        result = method(*self.path_args, **self.path_kwargs)
      File "/home/s0214/.conda/envs/monster/lib/python3.8/site-packages/tornado/web.py", line 3289, in wrapper
        url = self.get_login_url()
      File "/home/s0214/.conda/envs/monster/lib/python3.8/site-packages/jupyter_server/base/handlers.py", line 783, in get_login_url
        raise web.HTTPError(403)
    tornado.web.HTTPError: HTTP 403: Forbidden
[W 2025-09-26 17:22:45.723 ServerApp] 403 GET /api/kernels?1758889365706 (@172.16.33.3) 1.25ms referer=None
[W 2025-09-26 17:22:45.725 ServerApp] wrote error: 'Forbidden'
    Traceback (most recent call last):
      File "/home/s0214/.conda/envs/monster/lib/python3.8/site-packages/tornado/web.py", line 1788, in _execute
        result = method(*self.path_args, **self.path_kwargs)
      File "/home/s0214/.conda/envs/monster/lib/python3.8/site-packages/tornado/web.py", line 3289, in wrapper
        url = self.get_login_url()
      File "/home/s0214/.conda/envs/monster/lib/python3.8/site-packages/jupyter_server/base/handlers.py", line 783, in get_login_url
        raise web.HTTPError(403)
    tornado.web.HTTPError: HTTP 403: Forbidden
[W 2025-09-26 17:22:45.725 ServerApp] 403 GET /api/sessions?1758889365709 (@172.16.33.3) 1.75ms referer=None
[W 2025-09-26 17:22:45.726 ServerApp] wrote error: 'Forbidden'
    Traceback (most recent call last):
      File "/home/s0214/.conda/envs/monster/lib/python3.8/site-packages/tornado/web.py", line 1788, in _execute
        result = method(*self.path_args, **self.path_kwargs)
      File "/home/s0214/.conda/envs/monster/lib/python3.8/site-packages/tornado/web.py", line 3289, in wrapper
        url = self.get_login_url()
      File "/home/s0214/.conda/envs/monster/lib/python3.8/site-packages/jupyter_server/base/handlers.py", line 783, in get_login_url
        raise web.HTTPError(403)
    tornado.web.HTTPError: HTTP 403: Forbidden
[W 2025-09-26 17:22:45.726 ServerApp] 403 GET /api/kernels?1758889365710 (@172.16.33.3) 2.24ms referer=None
[W 2025-09-26 17:22:45.727 ServerApp] wrote error: 'Forbidden'
    Traceback (most recent call last):
      File "/home/s0214/.conda/envs/monster/lib/python3.8/site-packages/tornado/web.py", line 1788, in _execute
        result = method(*self.path_args, **self.path_kwargs)
      File "/home/s0214/.conda/envs/monster/lib/python3.8/site-packages/tornado/web.py", line 3289, in wrapper
        url = self.get_login_url()
      File "/home/s0214/.conda/envs/monster/lib/python3.8/site-packages/jupyter_server/base/handlers.py", line 783, in get_login_url
        raise web.HTTPError(403)
    tornado.web.HTTPError: HTTP 403: Forbidden
[W 2025-09-26 17:22:45.727 ServerApp] 403 GET /api/sessions?1758889365711 (@172.16.33.3) 2.79ms referer=None
[W 2025-09-26 17:22:45.729 ServerApp] wrote error: 'Forbidden'
    Traceback (most recent call last):
      File "/home/s0214/.conda/envs/monster/lib/python3.8/site-packages/tornado/web.py", line 1788, in _execute
        result = method(*self.path_args, **self.path_kwargs)
      File "/home/s0214/.conda/envs/monster/lib/python3.8/site-packages/tornado/web.py", line 3289, in wrapper
        url = self.get_login_url()
      File "/home/s0214/.conda/envs/monster/lib/python3.8/site-packages/jupyter_server/base/handlers.py", line 783, in get_login_url
        raise web.HTTPError(403)
    tornado.web.HTTPError: HTTP 403: Forbidden
[W 2025-09-26 17:22:45.729 ServerApp] 403 GET /api/kernelspecs?1758889365714 (@172.16.33.3) 1.69ms referer=None
[W 2025-09-26 17:22:45.729 ServerApp] wrote error: 'Forbidden'
    Traceback (most recent call last):
      File "/home/s0214/.conda/envs/monster/lib/python3.8/site-packages/tornado/web.py", line 1788, in _execute
        result = method(*self.path_args, **self.path_kwargs)
      File "/home/s0214/.conda/envs/monster/lib/python3.8/site-packages/tornado/web.py", line 3289, in wrapper
        url = self.get_login_url()
      File "/home/s0214/.conda/envs/monster/lib/python3.8/site-packages/jupyter_server/base/handlers.py", line 783, in get_login_url
        raise web.HTTPError(403)
    tornado.web.HTTPError: HTTP 403: Forbidden
[W 2025-09-26 17:22:45.730 ServerApp] 403 GET /api/kernelspecs?1758889365715 (@172.16.33.3) 2.21ms referer=None
[W 2025-09-26 17:22:45.730 ServerApp] wrote error: 'Forbidden'
    Traceback (most recent call last):
      File "/home/s0214/.conda/envs/monster/lib/python3.8/site-packages/tornado/web.py", line 1788, in _execute
        result = method(*self.path_args, **self.path_kwargs)
      File "/home/s0214/.conda/envs/monster/lib/python3.8/site-packages/tornado/web.py", line 3289, in wrapper
        url = self.get_login_url()
      File "/home/s0214/.conda/envs/monster/lib/python3.8/site-packages/jupyter_server/base/handlers.py", line 783, in get_login_url
        raise web.HTTPError(403)
    tornado.web.HTTPError: HTTP 403: Forbidden
[W 2025-09-26 17:22:45.731 ServerApp] 403 GET /api/kernelspecs?1758889365716 (@172.16.33.3) 2.75ms referer=None
[W 2025-09-26 17:22:48.169 ServerApp] 404 GET /nbextensions/jupyter-js-widgets/extension.js (@172.16.33.3) 40.52ms referer=None
[I 2025-09-26 17:22:48.169 ServerApp] 302 GET / (@172.16.33.3) 40.42ms
[I 2025-09-26 17:22:48.172 JupyterNotebookApp] 302 GET /tree? (@172.16.33.3) 0.63ms
[W 2025-09-26 17:22:48.181 ServerApp] 404 GET /nbextensions/jupyter-js-widgets/extension.js (@172.16.33.3) 1.27ms referer=None
slurmstepd: error: *** JOB 19585971 ON tesla-v100 CANCELLED AT 2025-09-26T17:30:28 ***
