The following values were not passed to `accelerate launch` and had defaults used instead:
		More than one GPU was found, enabling multi-GPU training.
		If this was unintended please pass in `--num_processes=1`.
	`--mixed_precision` was set to a value of `'no'`
	`--dynamo_backend` was set to a value of `'no'`
To avoid this warning pass in values for each of the problematic parameters or run `accelerate config`.
xFormers not available
xFormers not available
xFormers not available
xFormers not available
xFormers not available
xFormers not available
xFormers not available
xFormers not available
Error executing job with overrides: []
Traceback (most recent call last):
  File "train_whu.py", line 97, in main
    accelerator = Accelerator(mixed_precision='ff16', dataloader_config=DataLoaderConfiguration(use_seedable_sampler=True), log_with='wandb', kwargs_handlers=[kwargs], step_scheduler_with_optimizer=False)
  File "/home/s0214/.conda/envs/monster/lib/python3.8/site-packages/accelerate/accelerator.py", line 278, in __init__
    raise ValueError(
ValueError: Unknown mixed_precision mode: ff16. Choose between ['no', 'fp8', 'fp16', 'bf16']

Set the environment variable HYDRA_FULL_ERROR=1 for a complete stack trace.
Error executing job with overrides: []
Traceback (most recent call last):
  File "train_whu.py", line 97, in main
    accelerator = Accelerator(mixed_precision='ff16', dataloader_config=DataLoaderConfiguration(use_seedable_sampler=True), log_with='wandb', kwargs_handlers=[kwargs], step_scheduler_with_optimizer=False)
  File "/home/s0214/.conda/envs/monster/lib/python3.8/site-packages/accelerate/accelerator.py", line 278, in __init__
    raise ValueError(
ValueError: Unknown mixed_precision mode: ff16. Choose between ['no', 'fp8', 'fp16', 'bf16']

Set the environment variable HYDRA_FULL_ERROR=1 for a complete stack trace.
Error executing job with overrides: []
Traceback (most recent call last):
  File "train_whu.py", line 97, in main
    accelerator = Accelerator(mixed_precision='ff16', dataloader_config=DataLoaderConfiguration(use_seedable_sampler=True), log_with='wandb', kwargs_handlers=[kwargs], step_scheduler_with_optimizer=False)
  File "/home/s0214/.conda/envs/monster/lib/python3.8/site-packages/accelerate/accelerator.py", line 278, in __init__
    raise ValueError(
ValueError: Unknown mixed_precision mode: ff16. Choose between ['no', 'fp8', 'fp16', 'bf16']

Set the environment variable HYDRA_FULL_ERROR=1 for a complete stack trace.
[2025-08-10 21:48:35,662] torch.distributed.elastic.multiprocessing.api: [WARNING] Sending process 320566 closing signal SIGTERM
[2025-08-10 21:48:35,662] torch.distributed.elastic.multiprocessing.api: [WARNING] Sending process 320567 closing signal SIGTERM
[2025-08-10 21:48:35,662] torch.distributed.elastic.multiprocessing.api: [WARNING] Sending process 320569 closing signal SIGTERM
[2025-08-10 21:48:35,726] torch.distributed.elastic.multiprocessing.api: [ERROR] failed (exitcode: 1) local_rank: 2 (pid: 320568) of binary: /home/s0214/.conda/envs/monster/bin/python
Traceback (most recent call last):
  File "/home/s0214/.conda/envs/monster/bin/accelerate", line 8, in <module>
    sys.exit(main())
  File "/home/s0214/.conda/envs/monster/lib/python3.8/site-packages/accelerate/commands/accelerate_cli.py", line 48, in main
    args.func(args)
  File "/home/s0214/.conda/envs/monster/lib/python3.8/site-packages/accelerate/commands/launch.py", line 1159, in launch_command
    multi_gpu_launcher(args)
  File "/home/s0214/.conda/envs/monster/lib/python3.8/site-packages/accelerate/commands/launch.py", line 793, in multi_gpu_launcher
    distrib_run.run(args)
  File "/home/s0214/.conda/envs/monster/lib/python3.8/site-packages/torch/distributed/run.py", line 797, in run
    elastic_launch(
  File "/home/s0214/.conda/envs/monster/lib/python3.8/site-packages/torch/distributed/launcher/api.py", line 134, in __call__
    return launch_agent(self._config, self._entrypoint, list(args))
  File "/home/s0214/.conda/envs/monster/lib/python3.8/site-packages/torch/distributed/launcher/api.py", line 264, in launch_agent
    raise ChildFailedError(
torch.distributed.elastic.multiprocessing.errors.ChildFailedError: 
============================================================
train_whu.py FAILED
------------------------------------------------------------
Failures:
  <NO_OTHER_FAILURES>
------------------------------------------------------------
Root Cause (first observed failure):
[0]:
  time      : 2025-08-10_21:48:35
  host      : tesla-v100
  rank      : 2 (local_rank: 2)
  exitcode  : 1 (pid: 320568)
  error_file: <N/A>
  traceback : To enable traceback see: https://pytorch.org/docs/stable/elastic/errors.html
============================================================
